Workbook

Sheet ZoneGeneral_3D
A1: 번호 | B1: 존번호 | C1: 층 | D1: 존이름
A2: =IFERROR(IF(C2="","",IF(B2="",IF(ROW(C2)-1>99,C2&"F_Zone"&ROW(C2)-1,IF(ROW(C2)-1>9, C2&"F_Zone0"&ROW(C2)-1,C2&"F_Zone00"&ROW(C2)-1)),B2)),"") -> 1F_Zone002 | B2: 1F_Zone002 | C2: 1 | D2: 사무실
A3: =IFERROR(IF(C3="","",IF(B3="",IF(ROW(C3)-1>99,C3&"F_Zone"&ROW(C3)-1,IF(ROW(C3)-1>9, C3&"F_Zone0"&ROW(C3)-1,C3&"F_Zone00"&ROW(C3)-1)),B3)),"") -> 1F_Zone003 | B3: 1F_Zone003 | C3: 1 | D3: 복도_계단실
A4: =IFERROR(IF(C4="","",IF(B4="",IF(ROW(C4)-1>99,C4&"F_Zone"&ROW(C4)-1,IF(ROW(C4)-1>9, C4&"F_Zone0"&ROW(C4)-1,C4&"F_Zone00"&ROW(C4)-1)),B4)),"") -> 1F_Zone004 | B4: 1F_Zone004 | C4: 1 | D4: 화장실
A5: =IFERROR(IF(C5="","",IF(B5="",IF(ROW(C5)-1>99,C5&"F_Zone"&ROW(C5)-1,IF(ROW(C5)-1>9, C5&"F_Zone0"&ROW(C5)-1,C5&"F_Zone00"&ROW(C5)-1)),B5)),"") -> 1F_Zone005 | B5: 1F_Zone005 | C5: 1 | D5: 방풍실
A6: =IFERROR(IF(C6="","",IF(B6="",IF(ROW(C6)-1>99,C6&"F_Zone"&ROW(C6)-1,IF(ROW(C6)-1>9, C6&"F_Zone0"&ROW(C6)-1,C6&"F_Zone00"&ROW(C6)-1)),B6)),"") -> 2F_Zone006 | B6: 2F_Zone006 | C6: 2 | D6: 진압대기실
A7: =IFERROR(IF(C7="","",IF(B7="",IF(ROW(C7)-1>99,C7&"F_Zone"&ROW(C7)-1,IF(ROW(C7)-1>9, C7&"F_Zone0"&ROW(C7)-1,C7&"F_Zone00"&ROW(C7)-1)),B7)),"") -> 2F_Zone007 | B7: 2F_Zone007 | C7: 2 | D7: 구급대기실(남)
A8: =IFERROR(IF(C8="","",IF(B8="",IF(ROW(C8)-1>99,C8&"F_Zone"&ROW(C8)-1,IF(ROW(C8)-1>9, C8&"F_Zone0"&ROW(C8)-1,C8&"F_Zone00"&ROW(C8)-1)),B8)),"") -> 2F_Zone008 | B8: 2F_Zone008 | C8: 2 | D8: 복도
A9: =IFERROR(IF(C9="","",IF(B9="",IF(ROW(C9)-1>99,C9&"F_Zone"&ROW(C9)-1,IF(ROW(C9)-1>9, C9&"F_Zone0"&ROW(C9)-1,C9&"F_Zone00"&ROW(C9)-1)),B9)),"") -> 2F_Zone009 | B9: 2F_Zone009 | C9: 2 | D9: 심신안정실
A10: =IFERROR(IF(C10="","",IF(B10="",IF(ROW(C10)-1>99,C10&"F_Zone"&ROW(C10)-1,IF(ROW(C10)-1>9, C10&"F_Zone0"&ROW(C10)-1,C10&"F_Zone00"&ROW(C10)-1)),B10)),"") -> 2F_Zone010 | B10: 2F_Zone010 | C10: 2 | D10: 구급대기실(여)
A11: =IFERROR(IF(C11="","",IF(B11="",IF(ROW(C11)-1>99,C11&"F_Zone"&ROW(C11)-1,IF(ROW(C11)-1>9, C11&"F_Zone0"&ROW(C11)-1,C11&"F_Zone00"&ROW(C11)-1)),B11)),"") -> 2F_Zone011 | B11: 2F_Zone011 | C11: 2 | D11: 화장실_샤워실
A12: =IFERROR(IF(C12="","",IF(B12="",IF(ROW(C12)-1>99,C12&"F_Zone"&ROW(C12)-1,IF(ROW(C12)-1>9, C12&"F_Zone0"&ROW(C12)-1,C12&"F_Zone00"&ROW(C12)-1)),B12)),"") -> 2F_Zone012 | B12: 2F_Zone012 | C12: 2 | D12: 부소장실
A13: =IFERROR(IF(C13="","",IF(B13="",IF(ROW(C13)-1>99,C13&"F_Zone"&ROW(C13)-1,IF(ROW(C13)-1>9, C13&"F_Zone0"&ROW(C13)-1,C13&"F_Zone00"&ROW(C13)-1)),B13)),"") -> 2F_Zone013 | B13: 2F_Zone013 | C13: 2 | D13: 구급대기실(여)화장실
... A21: =IFERROR(IF(C21="","",IF(B21="",IF(ROW(C21)-1>99,C21&"F_Zone"&ROW(C21)-1,IF(ROW(C21)-1>9, C21&"F_Zone0"&ROW(C21)-1,C21&"F_Zone00"&ROW(C21)-1)),B21)),"") -> 4F_Zone021 | B21: 4F_Zone021 | C21: 4 | D21: 체력단련장
A22: =IFERROR(IF(C22="","",IF(B22="",IF(ROW(C22)-1>99,C22&"F_Zone"&ROW(C22)-1,IF(ROW(C22)-1>9, C22&"F_Zone0"&ROW(C22)-1,C22&"F_Zone00"&ROW(C22)-1)),B22)),"")
A23: =IFERROR(IF(C23="","",IF(B23="",IF(ROW(C23)-1>99,C23&"F_Zone"&ROW(C23)-1,IF(ROW(C23)-1>9, C23&"F_Zone0"&ROW(C23)-1,C23&"F_Zone00"&ROW(C23)-1)),B23)),"")
A24: =IFERROR(IF(C24="","",IF(B24="",IF(ROW(C24)-1>99,C24&"F_Zone"&ROW(C24)-1,IF(ROW(C24)-1>9, C24&"F_Zone0"&ROW(C24)-1,C24&"F_Zone00"&ROW(C24)-1)),B24)),"")
A25: =IFERROR(IF(C25="","",IF(B25="",IF(ROW(C25)-1>99,C25&"F_Zone"&ROW(C25)-1,IF(ROW(C25)-1>9, C25&"F_Zone0"&ROW(C25)-1,C25&"F_Zone00"&ROW(C25)-1)),B25)),"")
A26: =IFERROR(IF(C26="","",IF(B26="",IF(ROW(C26)-1>99,C26&"F_Zone"&ROW(C26)-1,IF(ROW(C26)-1>9, C26&"F_Zone0"&ROW(C26)-1,C26&"F_Zone00"&ROW(C26)-1)),B26)),"")
A27: =IFERROR(IF(C27="","",IF(B27="",IF(ROW(C27)-1>99,C27&"F_Zone"&ROW(C27)-1,IF(ROW(C27)-1>9, C27&"F_Zone0"&ROW(C27)-1,C27&"F_Zone00"&ROW(C27)-1)),B27)),"")
A28: =IFERROR(IF(C28="","",IF(B28="",IF(ROW(C28)-1>99,C28&"F_Zone"&ROW(C28)-1,IF(ROW(C28)-1>9, C28&"F_Zone0"&ROW(C28)-1,C28&"F_Zone00"&ROW(C28)-1)),B28)),"")
A29: =IFERROR(IF(C29="","",IF(B29="",IF(ROW(C29)-1>99,C29&"F_Zone"&ROW(C29)-1,IF(ROW(C29)-1>9, C29&"F_Zone0"&ROW(C29)-1,C29&"F_Zone00"&ROW(C29)-1)),B29)),"")
A30: =IFERROR(IF(C30="","",IF(B30="",IF(ROW(C30)-1>99,C30&"F_Zone"&ROW(C30)-1,IF(ROW(C30)-1>9, C30&"F_Zone0"&ROW(C30)-1,C30&"F_Zone00"&ROW(C30)-1)),B30)),"")
A31: =IFERROR(IF(C31="","",IF(B31="",IF(ROW(C31)-1>99,C31&"F_Zone"&ROW(C31)-1,IF(ROW(C31)-1>9, C31&"F_Zone0"&ROW(C31)-1,C31&"F_Zone00"&ROW(C31)-1)),B31)),"")
A32: =IFERROR(IF(C32="","",IF(B32="",IF(ROW(C32)-1>99,C32&"F_Zone"&ROW(C32)-1,IF(ROW(C32)-1>9, C32&"F_Zone0"&ROW(C32)-1,C32&"F_Zone00"&ROW(C32)-1)),B32)),"")
A33: =IFERROR(IF(C33="","",IF(B33="",IF(ROW(C33)-1>99,C33&"F_Zone"&ROW(C33)-1,IF(ROW(C33)-1>9, C33&"F_Zone0"&ROW(C33)-1,C33&"F_Zone00"&ROW(C33)-1)),B33)),"")
... A501: =IFERROR(IF(C501="","",IF(B501="",IF(ROW(C501)-1>99,C501&"F_Zone"&ROW(C501)-1,IF(ROW(C501)-1>9, C501&"F_Zone0"&ROW(C501)-1,C501&"F_Zone00"&ROW(C501)-1)),B501)),"")

Sheet ZoneEnvelope_3D
A1: 번호 | B1: 외피번호 | C1: 층 | D1: 존 | E1: 외피유형 | F1: 커튼월부위 | G1: 면적 | H1: 인접존 | I1: 방위 | J1: 기울기 | K1: 우측면돌출각도 | L1: 좌측면돌출각도 | M1: 상부돌출각도 | N1: 주변요소음영각도 | O1: 우측면돌출길이 | P1: 좌측면돌출길이 | Q1: 상부돌출길이 | R1: 주변요소음영길이 | S1: 벽체길이 | T1: 창호너비 | U1: 창호높이
A2: =IFERROR(IF(E2="","",IF(B2="",D2&"_"& IF($E2=외피index!$B$3, 외피index!$C$3&"_"&COUNTIFS(E2:$E$2,외피index!$B$3,D2:$D$2,D2), IF($E2=외피index!$B$4, 외피index!$C$4&"_"&COUNTIFS(E2:$E$2,외피index!$B$4,D2:$D$2,D2), IF($E2=외피index!$B$5, 외피index!$C$5&"_"&COUNTIFS(E2:$E$2,외피index!$B$5,D2:$D$2,D2), IF($E2=외피index!$B$6, 외피index!$C$6&"_"&COUNTIFS(E2:$E$2,외피index!$B$6,D2:$D$2,D2), IF($E2=외피index!$B$7, 외피index!$C$7&"_"&COUNTIFS(E2:$E$2,외피index!$B$7,D2:$D$2,D2), IF($E2=외피index!$B$8, 외피index!$C$8&"_"&COUNTIFS(E2:$E$2,외피index!$B$8,D2:$D$2,D2), IF($E2=외피index!$B$9, 외피index!$C$9&"_"&COUNTIFS(E2:$E$2,외피index!$B$9,D2:$D$2,D2), IF($E2=외피index!$B$10, 외피index!$C$10&"_"&COUNTIFS(E2:$E$2,외피index!$B$10,D2:$D$2,D2), 0)))))))),B2)),"") -> 2F_Zone006_SL_9 | B2: 2F_Zone006_SL_9 | C2: 2F | D2: 2F_Zone006 | E2: 층간바닥 | G2: 28.080031 | H2: 3F_Zone014 | I2: 수평 | J2: 180 | K2: 0 | L2: 0 | M2: 0 | N2: 0 | O2: 0 | P2: 0 | Q2: 0 | R2: 0 | S2: 0 | T2: 0 | U2: 0
A3: =IFERROR(IF(E3="","",IF(B3="",D3&"_"& IF($E3=외피index!$B$3, 외피index!$C$3&"_"&COUNTIFS(E$2:$E3,외피index!$B$3,D$2:$D3,D3), IF($E3=외피index!$B$4, 외피index!$C$4&"_"&COUNTIFS(E$2:$E3,외피index!$B$4,D$2:$D3,D3), IF($E3=외피index!$B$5, 외피index!$C$5&"_"&COUNTIFS(E$2:$E3,외피index!$B$5,D$2:$D3,D3), IF($E3=외피index!$B$6, 외피index!$C$6&"_"&COUNTIFS(E$2:$E3,외피index!$B$6,D$2:$D3,D3), IF($E3=외피index!$B$7, 외피index!$C$7&"_"&COUNTIFS(E$2:$E3,외피index!$B$7,D$2:$D3,D3), IF($E3=외피index!$B$8, 외피index!$C$8&"_"&COUNTIFS(E$2:$E3,외피index!$B$8,D$2:$D3,D3), IF($E3=외피index!$B$9, 외피index!$C$9&"_"&COUNTIFS(E$2:$E3,외피index!$B$9,D$2:$D3,D3), IF($E3=외피index!$B$10, 외피index!$C$10&"_"&COUNTIFS(E$2:$E3,외피index!$B$10,D$2:$D3,D3), 0)))))))),B3)),"") -> 2F_Zone007_SL_7 | B3: 2F_Zone007_SL_7 | C3: 2F | D3: 2F_Zone007 | E3: 층간바닥 | G3: 22.879955 | H3: 3F_Zone015 | I3: 수평 | J3: 180 | K3: 0 | L3: 0 | M3: 0 | N3: 0 | O3: 0 | P3: 0 | Q3: 0 | R3: 0 | S3: 0 | T3: 0 | U3: 0
A4: =IFERROR(IF(E4="","",IF(B4="",D4&"_"& IF($E4=외피index!$B$3, 외피index!$C$3&"_"&COUNTIFS(E$2:$E4,외피index!$B$3,D$2:$D4,D4), IF($E4=외피index!$B$4, 외피index!$C$4&"_"&COUNTIFS(E$2:$E4,외피index!$B$4,D$2:$D4,D4), IF($E4=외피index!$B$5, 외피index!$C$5&"_"&COUNTIFS(E$2:$E4,외피index!$B$5,D$2:$D4,D4), IF($E4=외피index!$B$6, 외피index!$C$6&"_"&COUNTIFS(E$2:$E4,외피index!$B$6,D$2:$D4,D4), IF($E4=외피index!$B$7, 외피index!$C$7&"_"&COUNTIFS(E$2:$E4,외피index!$B$7,D$2:$D4,D4), IF($E4=외피index!$B$8, 외피index!$C$8&"_"&COUNTIFS(E$2:$E4,외피index!$B$8,D$2:$D4,D4), IF($E4=외피index!$B$9, 외피index!$C$9&"_"&COUNTIFS(E$2:$E4,외피index!$B$9,D$2:$D4,D4), IF($E4=외피index!$B$10, 외피index!$C$10&"_"&COUNTIFS(E$2:$E4,외피index!$B$10,D$2:$D4,D4), 0)))))))),B4)),"") -> 2F_Zone011_RF_6 | B4: 2F_Zone011_RF_6 | C4: 2F | D4: 2F_Zone011 | E4: 지붕 | G4: 18.200043 | I4: 수평 | J4: 0 | K4: 0 | L4: 0 | M4: 0 | N4: 0 | O4: 0 | P4: 0 | Q4: 0 | R4: 0 | S4: 0 | T4: 0 | U4: 0
A5: =IFERROR(IF(E5="","",IF(B5="",D5&"_"& IF($E5=외피index!$B$3, 외피index!$C$3&"_"&COUNTIFS(E$2:$E5,외피index!$B$3,D$2:$D5,D5), IF($E5=외피index!$B$4, 외피index!$C$4&"_"&COUNTIFS(E$2:$E5,외피index!$B$4,D$2:$D5,D5), IF($E5=외피index!$B$5, 외피index!$C$5&"_"&COUNTIFS(E$2:$E5,외피index!$B$5,D$2:$D5,D5), IF($E5=외피index!$B$6, 외피index!$C$6&"_"&COUNTIFS(E$2:$E5,외피index!$B$6,D$2:$D5,D5), IF($E5=외피index!$B$7, 외피index!$C$7&"_"&COUNTIFS(E$2:$E5,외피index!$B$7,D$2:$D5,D5), IF($E5=외피index!$B$8, 외피index!$C$8&"_"&COUNTIFS(E$2:$E5,외피index!$B$8,D$2:$D5,D5), IF($E5=외피index!$B$9, 외피index!$C$9&"_"&COUNTIFS(E$2:$E5,외피index!$B$9,D$2:$D5,D5), IF($E5=외피index!$B$10, 외피index!$C$10&"_"&COUNTIFS(E$2:$E5,외피index!$B$10,D$2:$D5,D5), 0)))))))),B5)),"") -> 2F_Zone008_SL_7 | B5: 2F_Zone008_SL_7 | C5: 2F | D5: 2F_Zone008 | E5: 층간바닥 | G5: 15.449966 | H5: 3F_Zone016 | I5: 수평 | J5: 0 | K5: 0 | L5: 0 | M5: 0 | N5: 0 | O5: 0 | P5: 0 | Q5: 0 | R5: 0 | S5: 0 | T5: 0 | U5: 0
A6: =IFERROR(IF(E6="","",IF(B6="",D6&"_"& IF($E6=외피index!$B$3, 외피index!$C$3&"_"&COUNTIFS(E$2:$E6,외피index!$B$3,D$2:$D6,D6), IF($E6=외피index!$B$4, 외피index!$C$4&"_"&COUNTIFS(E$2:$E6,외피index!$B$4,D$2:$D6,D6), IF($E6=외피index!$B$5, 외피index!$C$5&"_"&COUNTIFS(E$2:$E6,외피index!$B$5,D$2:$D6,D6), IF($E6=외피index!$B$6, 외피index!$C$6&"_"&COUNTIFS(E$2:$E6,외피index!$B$6,D$2:$D6,D6), IF($E6=외피index!$B$7, 외피index!$C$7&"_"&COUNTIFS(E$2:$E6,외피index!$B$7,D$2:$D6,D6), IF($E6=외피index!$B$8, 외피index!$C$8&"_"&COUNTIFS(E$2:$E6,외피index!$B$8,D$2:$D6,D6), IF($E6=외피index!$B$9, 외피index!$C$9&"_"&COUNTIFS(E$2:$E6,외피index!$B$9,D$2:$D6,D6), IF($E6=외피index!$B$10, 외피index!$C$10&"_"&COUNTIFS(E$2:$E6,외피index!$B$10,D$2:$D6,D6), 0)))))))),B6)),"") -> 2F_Zone009_SL_6 | B6: 2F_Zone009_SL_6 | C6: 2F | D6: 2F_Zone009 | E6: 층간바닥 | G6: 14.040055 | H6: 3F_Zone015 | I6: 수평 | J6: 180 | K6: 0 | L6: 0 | M6: 0 | N6: 0 | O6: 0 | P6: 0 | Q6: 0 | R6: 0 | S6: 0 | T6: 0 | U6: 0
A7: =IFERROR(IF(E7="","",IF(B7="",D7&"_"& IF($E7=외피index!$B$3, 외피index!$C$3&"_"&COUNTIFS(E$2:$E7,외피index!$B$3,D$2:$D7,D7), IF($E7=외피index!$B$4, 외피index!$C$4&"_"&COUNTIFS(E$2:$E7,외피index!$B$4,D$2:$D7,D7), IF($E7=외피index!$B$5, 외피index!$C$5&"_"&COUNTIFS(E$2:$E7,외피index!$B$5,D$2:$D7,D7), IF($E7=외피index!$B$6, 외피index!$C$6&"_"&COUNTIFS(E$2:$E7,외피index!$B$6,D$2:$D7,D7), IF($E7=외피index!$B$7, 외피index!$C$7&"_"&COUNTIFS(E$2:$E7,외피index!$B$7,D$2:$D7,D7), IF($E7=외피index!$B$8, 외피index!$C$8&"_"&COUNTIFS(E$2:$E7,외피index!$B$8,D$2:$D7,D7), IF($E7=외피index!$B$9, 외피index!$C$9&"_"&COUNTIFS(E$2:$E7,외피index!$B$9,D$2:$D7,D7), IF($E7=외피index!$B$10, 외피index!$C$10&"_"&COUNTIFS(E$2:$E7,외피index!$B$10,D$2:$D7,D7), 0)))))))),B7)),"") -> 2F_Zone010_RF_10 | B7: 2F_Zone010_RF_10 | C7: 2F | D7: 2F_Zone010 | E7: 지붕 | G7: 10.920018 | I7: 수평 | J7: 0 | K7: 0 | L7: 0 | M7: 0 | N7: 0 | O7: 0 | P7: 0 | Q7: 0 | R7: 0 | S7: 0 | T7: 0 | U7: 0
A8: =IFERROR(IF(E8="","",IF(B8="",D8&"_"& IF($E8=외피index!$B$3, 외피index!$C$3&"_"&COUNTIFS(E$2:$E8,외피index!$B$3,D$2:$D8,D8), IF($E8=외피index!$B$4, 외피index!$C$4&"_"&COUNTIFS(E$2:$E8,외피index!$B$4,D$2:$D8,D8), IF($E8=외피index!$B$5, 외피index!$C$5&"_"&COUNTIFS(E$2:$E8,외피index!$B$5,D$2:$D8,D8), IF($E8=외피index!$B$6, 외피index!$C$6&"_"&COUNTIFS(E$2:$E8,외피index!$B$6,D$2:$D8,D8), IF($E8=외피index!$B$7, 외피index!$C$7&"_"&COUNTIFS(E$2:$E8,외피index!$B$7,D$2:$D8,D8), IF($E8=외피index!$B$8, 외피index!$C$8&"_"&COUNTIFS(E$2:$E8,외피index!$B$8,D$2:$D8,D8), IF($E8=외피index!$B$9, 외피index!$C$9&"_"&COUNTIFS(E$2:$E8,외피index!$B$9,D$2:$D8,D8), IF($E8=외피index!$B$10, 외피index!$C$10&"_"&COUNTIFS(E$2:$E8,외피index!$B$10,D$2:$D8,D8), 0)))))))),B8)),"") -> 2F_Zone006_SL_8 | B8: 2F_Zone006_SL_8 | C8: 2F | D8: 2F_Zone006 | E8: 층간바닥 | G8: 8.6799365 | H8: 3F_Zone017 | I8: 수평 | J8: 180 | K8: 0 | L8: 0 | M8: 0 | N8: 0 | O8: 0 | P8: 0 | Q8: 0 | R8: 0 | S8: 0 | T8: 0 | U8: 0
A9: =IFERROR(IF(E9="","",IF(B9="",D9&"_"& IF($E9=외피index!$B$3, 외피index!$C$3&"_"&COUNTIFS(E$2:$E9,외피index!$B$3,D$2:$D9,D9), IF($E9=외피index!$B$4, 외피index!$C$4&"_"&COUNTIFS(E$2:$E9,외피index!$B$4,D$2:$D9,D9), IF($E9=외피index!$B$5, 외피index!$C$5&"_"&COUNTIFS(E$2:$E9,외피index!$B$5,D$2:$D9,D9), IF($E9=외피index!$B$6, 외피index!$C$6&"_"&COUNTIFS(E$2:$E9,외피index!$B$6,D$2:$D9,D9), IF($E9=외피index!$B$7, 외피index!$C$7&"_"&COUNTIFS(E$2:$E9,외피index!$B$7,D$2:$D9,D9), IF($E9=외피index!$B$8, 외피index!$C$8&"_"&COUNTIFS(E$2:$E9,외피index!$B$8,D$2:$D9,D9), IF($E9=외피index!$B$9, 외피index!$C$9&"_"&COUNTIFS(E$2:$E9,외피index!$B$9,D$2:$D9,D9), IF($E9=외피index!$B$10, 외피index!$C$10&"_"&COUNTIFS(E$2:$E9,외피index!$B$10,D$2:$D9,D9), 0)))))))),B9)),"") -> 2F_Zone012_RF_7 | B9: 2F_Zone012_RF_7 | C9: 2F | D9: 2F_Zone012 | E9: 지붕 | G9: 7.5400415 | I9: 수평 | J9: 0 | K9: 0 | L9: 0 | M9: 0 | N9: 0 | O9: 0 | P9: 0 | Q9: 0 | R9: 0 | S9: 0 | T9: 0 | U9: 0
A10: =IFERROR(IF(E10="","",IF(B10="",D10&"_"& IF($E10=외피index!$B$3, 외피index!$C$3&"_"&COUNTIFS(E$2:$E10,외피index!$B$3,D$2:$D10,D10), IF($E10=외피index!$B$4, 외피index!$C$4&"_"&COUNTIFS(E$2:$E10,외피index!$B$4,D$2:$D10,D10), IF($E10=외피index!$B$5, 외피index!$C$5&"_"&COUNTIFS(E$2:$E10,외피index!$B$5,D$2:$D10,D10), IF($E10=외피index!$B$6, 외피index!$C$6&"_"&COUNTIFS(E$2:$E10,외피index!$B$6,D$2:$D10,D10), IF($E10=외피index!$B$7, 외피index!$C$7&"_"&COUNTIFS(E$2:$E10,외피index!$B$7,D$2:$D10,D10), IF($E10=외피index!$B$8, 외피index!$C$8&"_"&COUNTIFS(E$2:$E10,외피index!$B$8,D$2:$D10,D10), IF($E10=외피index!$B$9, 외피index!$C$9&"_"&COUNTIFS(E$2:$E10,외피index!$B$9,D$2:$D10,D10), IF($E10=외피index!$B$10, 외피index!$C$10&"_"&COUNTIFS(E$2:$E10,외피index!$B$10,D$2:$D10,D10), 0)))))))),B10)),"") -> 2F_Zone006_SL_7 | B10: 2F_Zone006_SL_7 | C10: 2F | D10: 2F_Zone006 | E10: 층간바닥 | G10: 5.8799915 | H10: 3F_Zone016 | I10: 수평 | J10: 0 | K10: 0 | L10: 0 | M10: 0 | N10: 0 | O10: 0 | P10: 0 | Q10: 0 | R10: 0 | S10: 0 | T10: 0 | U10: 0
A11: =IFERROR(IF(E11="","",IF(B11="",D11&"_"& IF($E11=외피index!$B$3, 외피index!$C$3&"_"&COUNTIFS(E$2:$E11,외피index!$B$3,D$2:$D11,D11), IF($E11=외피index!$B$4, 외피index!$C$4&"_"&COUNTIFS(E$2:$E11,외피index!$B$4,D$2:$D11,D11), IF($E11=외피index!$B$5, 외피index!$C$5&"_"&COUNTIFS(E$2:$E11,외피index!$B$5,D$2:$D11,D11), IF($E11=외피index!$B$6, 외피index!$C$6&"_"&COUNTIFS(E$2:$E11,외피index!$B$6,D$2:$D11,D11), IF($E11=외피index!$B$7, 외피index!$C$7&"_"&COUNTIFS(E$2:$E11,외피index!$B$7,D$2:$D11,D11), IF($E11=외피index!$B$8, 외피index!$C$8&"_"&COUNTIFS(E$2:$E11,외피index!$B$8,D$2:$D11,D11), IF($E11=외피index!$B$9, 외피index!$C$9&"_"&COUNTIFS(E$2:$E11,외피index!$B$9,D$2:$D11,D11), IF($E11=외피index!$B$10, 외피index!$C$10&"_"&COUNTIFS(E$2:$E11,외피index!$B$10,D$2:$D11,D11), 0)))))))),B11)),"") -> 2F_Zone008_SL_15 | B11: 2F_Zone008_SL_15 | C11: 2F | D11: 2F_Zone008 | E11: 층간바닥 | G11: 5.5822345 | H11: 3F_Zone019 | I11: 수평 | J11: 0 | K11: 0 | L11: 0 | M11: 0 | N11: 0 | O11: 0 | P11: 0 | Q11: 0 | R11: 0 | S11: 0 | T11: 0 | U11: 0
A12: =IFERROR(IF(E12="","",IF(B12="",D12&"_"& IF($E12=외피index!$B$3, 외피index!$C$3&"_"&COUNTIFS(E$2:$E12,외피index!$B$3,D$2:$D12,D12), IF($E12=외피index!$B$4, 외피index!$C$4&"_"&COUNTIFS(E$2:$E12,외피index!$B$4,D$2:$D12,D12), IF($E12=외피index!$B$5, 외피index!$C$5&"_"&COUNTIFS(E$2:$E12,외피index!$B$5,D$2:$D12,D12), IF($E12=외피index!$B$6, 외피index!$C$6&"_"&COUNTIFS(E$2:$E12,외피index!$B$6,D$2:$D12,D12), IF($E12=외피index!$B$7, 외피index!$C$7&"_"&COUNTIFS(E$2:$E12,외피index!$B$7,D$2:$D12,D12), IF($E12=외피index!$B$8, 외피index!$C$8&"_"&COUNTIFS(E$2:$E12,외피index!$B$8,D$2:$D12,D12), IF($E12=외피index!$B$9, 외피index!$C$9&"_"&COUNTIFS(E$2:$E12,외피index!$B$9,D$2:$D12,D12), IF($E12=외피index!$B$10, 외피index!$C$10&"_"&COUNTIFS(E$2:$E12,외피index!$B$10,D$2:$D12,D12), 0)))))))),B12)),"") -> 2F_Zone013_SL_7 | B12: 2F_Zone013_SL_7 | C12: 2F | D12: 2F_Zone013 | E12: 층간바닥 | G12: 4.7999878 | H12: 3F_Zone020 | I12: 수평 | J12: 180 | K12: 0 | L12: 0 | M12: 0 | N12: 0 | O12: 0 | P12: 0 | Q12: 0 | R12: 0 | S12: 0 | T12: 0 | U12: 0
A13: =IFERROR(IF(E13="","",IF(B13="",D13&"_"& IF($E13=외피index!$B$3, 외피index!$C$3&"_"&COUNTIFS(E$2:$E13,외피index!$B$3,D$2:$D13,D13), IF($E13=외피index!$B$4, 외피index!$C$4&"_"&COUNTIFS(E$2:$E13,외피index!$B$4,D$2:$D13,D13), IF($E13=외피index!$B$5, 외피index!$C$5&"_"&COUNTIFS(E$2:$E13,외피index!$B$5,D$2:$D13,D13), IF($E13=외피index!$B$6, 외피index!$C$6&"_"&COUNTIFS(E$2:$E13,외피index!$B$6,D$2:$D13,D13), IF($E13=외피index!$B$7, 외피index!$C$7&"_"&COUNTIFS(E$2:$E13,외피index!$B$7,D$2:$D13,D13), IF($E13=외피index!$B$8, 외피index!$C$8&"_"&COUNTIFS(E$2:$E13,외피index!$B$8,D$2:$D13,D13), IF($E13=외피index!$B$9, 외피index!$C$9&"_"&COUNTIFS(E$2:$E13,외피index!$B$9,D$2:$D13,D13), IF($E13=외피index!$B$10, 외피index!$C$10&"_"&COUNTIFS(E$2:$E13,외피index!$B$10,D$2:$D13,D13), 0)))))))),B13)),"") -> 2F_Zone012_SL_9 | B13: 2F_Zone012_SL_9 | C13: 2F | D13: 2F_Zone012 | E13: 층간바닥 | G13: 1.8900087 | H13: 3F_Zone018 | I13: 수평 | J13: 0 | K13: 0 | L13: 0 | M13: 0 | N13: 0 | O13: 0 | P13: 0 | Q13: 0 | R13: 0 | S13: 0 | T13: 0 | U13: 0
A14: =IFERROR(IF(E14="","",IF(B14="",D14&"_"& IF($E14=외피index!$B$3, 외피index!$C$3&"_"&COUNTIFS(E$2:$E14,외피index!$B$3,D$2:$D14,D14), IF($E14=외피index!$B$4, 외피index!$C$4&"_"&COUNTIFS(E$2:$E14,외피index!$B$4,D$2:$D14,D14), IF($E14=외피index!$B$5, 외피index!$C$5&"_"&COUNTIFS(E$2:$E14,외피index!$B$5,D$2:$D14,D14), IF($E14=외피index!$B$6, 외피index!$C$6&"_"&COUNTIFS(E$2:$E14,외피index!$B$6,D$2:$D14,D14), IF($E14=외피index!$B$7, 외피index!$C$7&"_"&COUNTIFS(E$2:$E14,외피index!$B$7,D$2:$D14,D14), IF($E14=외피index!$B$8, 외피index!$C$8&"_"&COUNTIFS(E$2:$E14,외피index!$B$8,D$2:$D14,D14), IF($E14=외피index!$B$9, 외피index!$C$9&"_"&COUNTIFS(E$2:$E14,외피index!$B$9,D$2:$D14,D14), IF($E14=외피index!$B$10, 외피index!$C$10&"_"&COUNTIFS(E$2:$E14,외피index!$B$10,D$2:$D14,D14), 0)))))))),B14)),"") -> 2F_Zone010_SL_8 | B14: 2F_Zone010_SL_8 | C14: 2F | D14: 2F_Zone010 | E14: 층간바닥 | G14: 1.7167492 | H14: 3F_Zone019 | I14: 수평 | J14: 0 | K14: 0 | L14: 0 | M14: 0 | N14: 0 | O14: 0 | P14: 0 | Q14: 0 | R14: 0 | S14: 0 | T14: 0 | U14: 0
A15: =IFERROR(IF(E15="","",IF(B15="",D15&"_"& IF($E15=외피index!$B$3, 외피index!$C$3&"_"&COUNTIFS(E$2:$E15,외피index!$B$3,D$2:$D15,D15), IF($E15=외피index!$B$4, 외피index!$C$4&"_"&COUNTIFS(E$2:$E15,외피index!$B$4,D$2:$D15,D15), IF($E15=외피index!$B$5, 외피index!$C$5&"_"&COUNTIFS(E$2:$E15,외피index!$B$5,D$2:$D15,D15), IF($E15=외피index!$B$6, 외피index!$C$6&"_"&COUNTIFS(E$2:$E15,외피index!$B$6,D$2:$D15,D15), IF($E15=외피index!$B$7, 외피index!$C$7&"_"&COUNTIFS(E$2:$E15,외피index!$B$7,D$2:$D15,D15), IF($E15=외피index!$B$8, 외피index!$C$8&"_"&COUNTIFS(E$2:$E15,외피index!$B$8,D$2:$D15,D15), IF($E15=외피index!$B$9, 외피index!$C$9&"_"&COUNTIFS(E$2:$E15,외피index!$B$9,D$2:$D15,D15), IF($E15=외피index!$B$10, 외피index!$C$10&"_"&COUNTIFS(E$2:$E15,외피index!$B$10,D$2:$D15,D15), 0)))))))),B15)),"") -> 2F_Zone012_SL_8 | B15: 2F_Zone012_SL_8 | C15: 2F | D15: 2F_Zone012 | E15: 층간바닥 | G15: 1.1550098 | H15: 3F_Zone019 | I15: 수평 | J15: 0 | K15: 0 | L15: 0 | M15: 0 | N15: 0 | O15: 0 | P15: 0 | Q15: 0 | R15: 0 | S15: 0 | T15: 0 | U15: 0
A16: =IFERROR(IF(E16="","",IF(B16="",D16&"_"& IF($E16=외피index!$B$3, 외피index!$C$3&"_"&COUNTIFS(E$2:$E16,외피index!$B$3,D$2:$D16,D16), IF($E16=외피index!$B$4, 외피index!$C$4&"_"&COUNTIFS(E$2:$E16,외피index!$B$4,D$2:$D16,D16), IF($E16=외피index!$B$5, 외피index!$C$5&"_"&COUNTIFS(E$2:$E16,외피index!$B$5,D$2:$D16,D16), IF($E16=외피index!$B$6, 외피index!$C$6&"_"&COUNTIFS(E$2:$E16,외피index!$B$6,D$2:$D16,D16), IF($E16=외피index!$B$7, 외피index!$C$7&"_"&COUNTIFS(E$2:$E16,외피index!$B$7,D$2:$D16,D16), IF($E16=외피index!$B$8, 외피index!$C$8&"_"&COUNTIFS(E$2:$E16,외피index!$B$8,D$2:$D16,D16), IF($E16=외피index!$B$9, 외피index!$C$9&"_"&COUNTIFS(E$2:$E16,외피index!$B$9,D$2:$D16,D16), IF($E16=외피index!$B$10, 외피index!$C$10&"_"&COUNTIFS(E$2:$E16,외피index!$B$10,D$2:$D16,D16), 0)))))))),B16)),"") -> 2F_Zone008_SL_16 | B16: 2F_Zone008_SL_16 | C16: 2F | D16: 2F_Zone008 | E16: 층간바닥 | G16: 0.76274812 | H16: 3F_Zone020 | I16: 수평 | J16: 0 | K16: 0 | L16: 0 | M16: 0 | N16: 0 | O16: 0 | P16: 0 | Q16: 0 | R16: 0 | S16: 0 | T16: 0 | U16: 0
A17: =IFERROR(IF(E17="","",IF(B17="",D17&"_"& IF($E17=외피index!$B$3, 외피index!$C$3&"_"&COUNTIFS(E$2:$E17,외피index!$B$3,D$2:$D17,D17), IF($E17=외피index!$B$4, 외피index!$C$4&"_"&COUNTIFS(E$2:$E17,외피index!$B$4,D$2:$D17,D17), IF($E17=외피index!$B$5, 외피index!$C$5&"_"&COUNTIFS(E$2:$E17,외피index!$B$5,D$2:$D17,D17), IF($E17=외피index!$B$6, 외피index!$C$6&"_"&COUNTIFS(E$2:$E17,외피index!$B$6,D$2:$D17,D17), IF($E17=외피index!$B$7, 외피index!$C$7&"_"&COUNTIFS(E$2:$E17,외피index!$B$7,D$2:$D17,D17), IF($E17=외피index!$B$8, 외피index!$C$8&"_"&COUNTIFS(E$2:$E17,외피index!$B$8,D$2:$D17,D17), IF($E17=외피index!$B$9, 외피index!$C$9&"_"&COUNTIFS(E$2:$E17,외피index!$B$9,D$2:$D17,D17), IF($E17=외피index!$B$10, 외피index!$C$10&"_"&COUNTIFS(E$2:$E17,외피index!$B$10,D$2:$D17,D17), 0)))))))),B17)),"") -> 2F_Zone010_SL_9 | B17: 2F_Zone010_SL_9 | C17: 2F | D17: 2F_Zone010 | E17: 층간바닥 | G17: 0.59325429 | H17: 3F_Zone020 | I17: 수평 | J17: 0 | K17: 0 | L17: 0 | M17: 0 | N17: 0 | O17: 0 | P17: 0 | Q17: 0 | R17: 0 | S17: 0 | T17: 0 | U17: 0
A18: =IFERROR(IF(E18="","",IF(B18="",D18&"_"& IF($E18=외피index!$B$3, 외피index!$C$3&"_"&COUNTIFS(E$2:$E18,외피index!$B$3,D$2:$D18,D18), IF($E18=외피index!$B$4, 외피index!$C$4&"_"&COUNTIFS(E$2:$E18,외피index!$B$4,D$2:$D18,D18), IF($E18=외피index!$B$5, 외피index!$C$5&"_"&COUNTIFS(E$2:$E18,외피index!$B$5,D$2:$D18,D18), IF($E18=외피index!$B$6, 외피index!$C$6&"_"&COUNTIFS(E$2:$E18,외피index!$B$6,D$2:$D18,D18), IF($E18=외피index!$B$7, 외피index!$C$7&"_"&COUNTIFS(E$2:$E18,외피index!$B$7,D$2:$D18,D18), IF($E18=외피index!$B$8, 외피index!$C$8&"_"&COUNTIFS(E$2:$E18,외피index!$B$8,D$2:$D18,D18), IF($E18=외피index!$B$9, 외피index!$C$9&"_"&COUNTIFS(E$2:$E18,외피index!$B$9,D$2:$D18,D18), IF($E18=외피index!$B$10, 외피index!$C$10&"_"&COUNTIFS(E$2:$E18,외피index!$B$10,D$2:$D18,D18), 0)))))))),B18)),"") -> 3F_Zone015_RF_7 | B18: 3F_Zone015_RF_7 | C18: 3F | D18: 3F_Zone015 | E18: 지붕 | G18: 36.92001 | I18: 수평 | J18: 0 | K18: 0 | L18: 0 | M18: 0 | N18: 0 | O18: 0 | P18: 0 | Q18: 0 | R18: 0 | S18: 0 | T18: 0 | U18: 0
A19: =IFERROR(IF(E19="","",IF(B19="",D19&"_"& IF($E19=외피index!$B$3, 외피index!$C$3&"_"&COUNTIFS(E$2:$E19,외피index!$B$3,D$2:$D19,D19), IF($E19=외피index!$B$4, 외피index!$C$4&"_"&COUNTIFS(E$2:$E19,외피index!$B$4,D$2:$D19,D19), IF($E19=외피index!$B$5, 외피index!$C$5&"_"&COUNTIFS(E$2:$E19,외피index!$B$5,D$2:$D19,D19), IF($E19=외피index!$B$6, 외피index!$C$6&"_"&COUNTIFS(E$2:$E19,외피index!$B$6,D$2:$D19,D19), IF($E19=외피index!$B$7, 외피index!$C$7&"_"&COUNTIFS(E$2:$E19,외피index!$B$7,D$2:$D19,D19), IF($E19=외피index!$B$8, 외피index!$C$8&"_"&COUNTIFS(E$2:$E19,외피index!$B$8,D$2:$D19,D19), IF($E19=외피index!$B$9, 외피index!$C$9&"_"&COUNTIFS(E$2:$E19,외피index!$B$9,D$2:$D19,D19), IF($E19=외피index!$B$10, 외피index!$C$10&"_"&COUNTIFS(E$2:$E19,외피index!$B$10,D$2:$D19,D19), 0)))))))),B19)),"") -> 3F_Zone014_RF_8 | B19: 3F_Zone014_RF_8 | C19: 3F | D19: 3F_Zone014 | E19: 지붕 | G19: 28.080031 | I19: 수평 | J19: 0 | K19: 0 | L19: 0 | M19: 0 | N19: 0 | O19: 0 | P19: 0 | Q19: 0 | R19: 0 | S19: 0 | T19: 0 | U19: 0
A20: =IFERROR(IF(E20="","",IF(B20="",D20&"_"& IF($E20=외피index!$B$3, 외피index!$C$3&"_"&COUNTIFS(E$2:$E20,외피index!$B$3,D$2:$D20,D20), IF($E20=외피index!$B$4, 외피index!$C$4&"_"&COUNTIFS(E$2:$E20,외피index!$B$4,D$2:$D20,D20), IF($E20=외피index!$B$5, 외피index!$C$5&"_"&COUNTIFS(E$2:$E20,외피index!$B$5,D$2:$D20,D20), IF($E20=외피index!$B$6, 외피index!$C$6&"_"&COUNTIFS(E$2:$E20,외피index!$B$6,D$2:$D20,D20), IF($E20=외피index!$B$7, 외피index!$C$7&"_"&COUNTIFS(E$2:$E20,외피index!$B$7,D$2:$D20,D20), IF($E20=외피index!$B$8, 외피index!$C$8&"_"&COUNTIFS(E$2:$E20,외피index!$B$8,D$2:$D20,D20), IF($E20=외피index!$B$9, 외피index!$C$9&"_"&COUNTIFS(E$2:$E20,외피index!$B$9,D$2:$D20,D20), IF($E20=외피index!$B$10, 외피index!$C$10&"_"&COUNTIFS(E$2:$E20,외피index!$B$10,D$2:$D20,D20), 0)))))))),B20)),"") -> 3F_Zone016_SL_8 | B20: 3F_Zone016_SL_8 | C20: 3F | D20: 3F_Zone016 | E20: 층간바닥 | G20: 15.449966 | H20: 4F_Zone021 | I20: 수평 | J20: 180 | K20: 0 | L20: 0 | M20: 0 | N20: 0 | O20: 0 | P20: 0 | Q20: 0 | R20: 0 | S20: 0 | T20: 0 | U20: 0
A21: =IFERROR(IF(E21="","",IF(B21="",D21&"_"& IF($E21=외피index!$B$3, 외피index!$C$3&"_"&COUNTIFS(E$2:$E21,외피index!$B$3,D$2:$D21,D21), IF($E21=외피index!$B$4, 외피index!$C$4&"_"&COUNTIFS(E$2:$E21,외피index!$B$4,D$2:$D21,D21), IF($E21=외피index!$B$5, 외피index!$C$5&"_"&COUNTIFS(E$2:$E21,외피index!$B$5,D$2:$D21,D21), IF($E21=외피index!$B$6, 외피index!$C$6&"_"&COUNTIFS(E$2:$E21,외피index!$B$6,D$2:$D21,D21), IF($E21=외피index!$B$7, 외피index!$C$7&"_"&COUNTIFS(E$2:$E21,외피index!$B$7,D$2:$D21,D21), IF($E21=외피index!$B$8, 외피index!$C$8&"_"&COUNTIFS(E$2:$E21,외피index!$B$8,D$2:$D21,D21), IF($E21=외피index!$B$9, 외피index!$C$9&"_"&COUNTIFS(E$2:$E21,외피index!$B$9,D$2:$D21,D21), IF($E21=외피index!$B$10, 외피index!$C$10&"_"&COUNTIFS(E$2:$E21,외피index!$B$10,D$2:$D21,D21), 0)))))))),B21)),"") -> 3F_Zone017_RF_6 | B21: 3F_Zone017_RF_6 | C21: 3F | D21: 3F_Zone017 | E21: 지붕 | G21: 8.6799365 | I21: 수평 | J21: 0 | K21: 0 | L21: 0 | M21: 0 | N21: 0 | O21: 0 | P21: 0 | Q21: 0 | R21: 0 | S21: 0 | T21: 0 | U21: 0
A22: =IFERROR(IF(E22="","",IF(B22="",D22&"_"& IF($E22=외피index!$B$3, 외피index!$C$3&"_"&COUNTIFS(E$2:$E22,외피index!$B$3,D$2:$D22,D22), IF($E22=외피index!$B$4, 외피index!$C$4&"_"&COUNTIFS(E$2:$E22,외피index!$B$4,D$2:$D22,D22), IF($E22=외피index!$B$5, 외피index!$C$5&"_"&COUNTIFS(E$2:$E22,외피index!$B$5,D$2:$D22,D22), IF($E22=외피index!$B$6, 외피index!$C$6&"_"&COUNTIFS(E$2:$E22,외피index!$B$6,D$2:$D22,D22), IF($E22=외피index!$B$7, 외피index!$C$7&"_"&COUNTIFS(E$2:$E22,외피index!$B$7,D$2:$D22,D22), IF($E22=외피index!$B$8, 외피index!$C$8&"_"&COUNTIFS(E$2:$E22,외피index!$B$8,D$2:$D22,D22), IF($E22=외피index!$B$9, 외피index!$C$9&"_"&COUNTIFS(E$2:$E22,외피index!$B$9,D$2:$D22,D22), IF($E22=외피index!$B$10, 외피index!$C$10&"_"&COUNTIFS(E$2:$E22,외피index!$B$10,D$2:$D22,D22), 0)))))))),B22)),"") -> 3F_Zone019_RF_6 | B22: 3F_Zone019_RF_6 | C22: 3F | D22: 3F_Zone019 | E22: 지붕 | G22: 8.4539935 | I22: 수평 | J22: 0 | K22: 0 | L22: 0 | M22: 0 | N22: 0 | O22: 0 | P22: 0 | Q22: 0 | R22: 0 | S22: 0 | T22: 0 | U22: 0
A23: =IFERROR(IF(E23="","",IF(B23="",D23&"_"& IF($E23=외피index!$B$3, 외피index!$C$3&"_"&COUNTIFS(E$2:$E23,외피index!$B$3,D$2:$D23,D23), IF($E23=외피index!$B$4, 외피index!$C$4&"_"&COUNTIFS(E$2:$E23,외피index!$B$4,D$2:$D23,D23), IF($E23=외피index!$B$5, 외피index!$C$5&"_"&COUNTIFS(E$2:$E23,외피index!$B$5,D$2:$D23,D23), IF($E23=외피index!$B$6, 외피index!$C$6&"_"&COUNTIFS(E$2:$E23,외피index!$B$6,D$2:$D23,D23), IF($E23=외피index!$B$7, 외피index!$C$7&"_"&COUNTIFS(E$2:$E23,외피index!$B$7,D$2:$D23,D23), IF($E23=외피index!$B$8, 외피index!$C$8&"_"&COUNTIFS(E$2:$E23,외피index!$B$8,D$2:$D23,D23), IF($E23=외피index!$B$9, 외피index!$C$9&"_"&COUNTIFS(E$2:$E23,외피index!$B$9,D$2:$D23,D23), IF($E23=외피index!$B$10, 외피index!$C$10&"_"&COUNTIFS(E$2:$E23,외피index!$B$10,D$2:$D23,D23), 0)))))))),B23)),"") -> 3F_Zone020_RF_7 | B23: 3F_Zone020_RF_7 | C23: 3F | D23: 3F_Zone020 | E23: 지붕 | G23: 6.1559902 | I23: 수평 | J23: 0 | K23: 0 | L23: 0 | M23: 0 | N23: 0 | O23: 0 | P23: 0 | Q23: 0 | R23: 0 | S23: 0 | T23: 0 | U23: 0
A24: =IFERROR(IF(E24="","",IF(B24="",D24&"_"& IF($E24=외피index!$B$3, 외피index!$C$3&"_"&COUNTIFS(E$2:$E24,외피index!$B$3,D$2:$D24,D24), IF($E24=외피index!$B$4, 외피index!$C$4&"_"&COUNTIFS(E$2:$E24,외피index!$B$4,D$2:$D24,D24), IF($E24=외피index!$B$5, 외피index!$C$5&"_"&COUNTIFS(E$2:$E24,외피index!$B$5,D$2:$D24,D24), IF($E24=외피index!$B$6, 외피index!$C$6&"_"&COUNTIFS(E$2:$E24,외피index!$B$6,D$2:$D24,D24), IF($E24=외피index!$B$7, 외피index!$C$7&"_"&COUNTIFS(E$2:$E24,외피index!$B$7,D$2:$D24,D24), IF($E24=외피index!$B$8, 외피index!$C$8&"_"&COUNTIFS(E$2:$E24,외피index!$B$8,D$2:$D24,D24), IF($E24=외피index!$B$9, 외피index!$C$9&"_"&COUNTIFS(E$2:$E24,외피index!$B$9,D$2:$D24,D24), IF($E24=외피index!$B$10, 외피index!$C$10&"_"&COUNTIFS(E$2:$E24,외피index!$B$10,D$2:$D24,D24), 0)))))))),B24)),"") -> 3F_Zone016_RF_15 | B24: 3F_Zone016_RF_15 | C24: 3F | D24: 3F_Zone016 | E24: 지붕 | G24: 5.8799915 | I24: 수평 | J24: 0 | K24: 0 | L24: 0 | M24: 0 | N24: 0 | O24: 0 | P24: 0 | Q24: 0 | R24: 0 | S24: 0 | T24: 0 | U24: 0
A25: =IFERROR(IF(E25="","",IF(B25="",D25&"_"& IF($E25=외피index!$B$3, 외피index!$C$3&"_"&COUNTIFS(E$2:$E25,외피index!$B$3,D$2:$D25,D25), IF($E25=외피index!$B$4, 외피index!$C$4&"_"&COUNTIFS(E$2:$E25,외피index!$B$4,D$2:$D25,D25), IF($E25=외피index!$B$5, 외피index!$C$5&"_"&COUNTIFS(E$2:$E25,외피index!$B$5,D$2:$D25,D25), IF($E25=외피index!$B$6, 외피index!$C$6&"_"&COUNTIFS(E$2:$E25,외피index!$B$6,D$2:$D25,D25), IF($E25=외피index!$B$7, 외피index!$C$7&"_"&COUNTIFS(E$2:$E25,외피index!$B$7,D$2:$D25,D25), IF($E25=외피index!$B$8, 외피index!$C$8&"_"&COUNTIFS(E$2:$E25,외피index!$B$8,D$2:$D25,D25), IF($E25=외피index!$B$9, 외피index!$C$9&"_"&COUNTIFS(E$2:$E25,외피index!$B$9,D$2:$D25,D25), IF($E25=외피index!$B$10, 외피index!$C$10&"_"&COUNTIFS(E$2:$E25,외피index!$B$10,D$2:$D25,D25), 0)))))))),B25)),"") -> 3F_Zone018_RF_8 | B25: 3F_Zone018_RF_8 | C25: 3F | D25: 3F_Zone018 | E25: 지붕 | G25: 2.4299876 | I25: 수평 | J25: 0 | K25: 0 | L25: 0 | M25: 0 | N25: 0 | O25: 0 | P25: 0 | Q25: 0 | R25: 0 | S25: 0 | T25: 0 | U25: 0
A26: =IFERROR(IF(E26="","",IF(B26="",D26&"_"& IF($E26=외피index!$B$3, 외피index!$C$3&"_"&COUNTIFS(E$2:$E26,외피index!$B$3,D$2:$D26,D26), IF($E26=외피index!$B$4, 외피index!$C$4&"_"&COUNTIFS(E$2:$E26,외피index!$B$4,D$2:$D26,D26), IF($E26=외피index!$B$5, 외피index!$C$5&"_"&COUNTIFS(E$2:$E26,외피index!$B$5,D$2:$D26,D26), IF($E26=외피index!$B$6, 외피index!$C$6&"_"&COUNTIFS(E$2:$E26,외피index!$B$6,D$2:$D26,D26), IF($E26=외피index!$B$7, 외피index!$C$7&"_"&COUNTIFS(E$2:$E26,외피index!$B$7,D$2:$D26,D26), IF($E26=외피index!$B$8, 외피index!$C$8&"_"&COUNTIFS(E$2:$E26,외피index!$B$8,D$2:$D26,D26), IF($E26=외피index!$B$9, 외피index!$C$9&"_"&COUNTIFS(E$2:$E26,외피index!$B$9,D$2:$D26,D26), IF($E26=외피index!$B$10, 외피index!$C$10&"_"&COUNTIFS(E$2:$E26,외피index!$B$10,D$2:$D26,D26), 0)))))))),B26)),"") -> 3F_Zone018_SL_9 | B26: 3F_Zone018_SL_9 | C26: 3F | D26: 3F_Zone018 | E26: 층간바닥 | G26: 1.3499908 | H26: 4F_Zone021 | I26: 수평 | J26: 180 | K26: 0 | L26: 0 | M26: 0 | N26: 0 | O26: 0 | P26: 0 | Q26: 0 | R26: 0 | S26: 0 | T26: 0 | U26: 0
A27: =IFERROR(IF(E27="","",IF(B27="",D27&"_"& IF($E27=외피index!$B$3, 외피index!$C$3&"_"&COUNTIFS(E$2:$E27,외피index!$B$3,D$2:$D27,D27), IF($E27=외피index!$B$4, 외피index!$C$4&"_"&COUNTIFS(E$2:$E27,외피index!$B$4,D$2:$D27,D27), IF($E27=외피index!$B$5, 외피index!$C$5&"_"&COUNTIFS(E$2:$E27,외피index!$B$5,D$2:$D27,D27), IF($E27=외피index!$B$6, 외피index!$C$6&"_"&COUNTIFS(E$2:$E27,외피index!$B$6,D$2:$D27,D27), IF($E27=외피index!$B$7, 외피index!$C$7&"_"&COUNTIFS(E$2:$E27,외피index!$B$7,D$2:$D27,D27), IF($E27=외피index!$B$8, 외피index!$C$8&"_"&COUNTIFS(E$2:$E27,외피index!$B$8,D$2:$D27,D27), IF($E27=외피index!$B$9, 외피index!$C$9&"_"&COUNTIFS(E$2:$E27,외피index!$B$9,D$2:$D27,D27), IF($E27=외피index!$B$10, 외피index!$C$10&"_"&COUNTIFS(E$2:$E27,외피index!$B$10,D$2:$D27,D27), 0)))))))),B27)),"") -> 1F_Zone002_SL_9 | B27: 1F_Zone002_SL_9 | C27: 1F | D27: 1F_Zone002 | E27: 층간바닥 | G27: 42.639959 | H27: 2F_Zone006 | I27: 수평 | J27: 0 | K27: 0 | L27: 0 | M27: 0 | N27: 0 | O27: 0 | P27: 0 | Q27: 0 | R27: 0 | S27: 0 | T27: 0 | U27: 0
A28: =IFERROR(IF(E28="","",IF(B28="",D28&"_"& IF($E28=외피index!$B$3, 외피index!$C$3&"_"&COUNTIFS(E$2:$E28,외피index!$B$3,D$2:$D28,D28), IF($E28=외피index!$B$4, 외피index!$C$4&"_"&COUNTIFS(E$2:$E28,외피index!$B$4,D$2:$D28,D28), IF($E28=외피index!$B$5, 외피index!$C$5&"_"&COUNTIFS(E$2:$E28,외피index!$B$5,D$2:$D28,D28), IF($E28=외피index!$B$6, 외피index!$C$6&"_"&COUNTIFS(E$2:$E28,외피index!$B$6,D$2:$D28,D28), IF($E28=외피index!$B$7, 외피index!$C$7&"_"&COUNTIFS(E$2:$E28,외피index!$B$7,D$2:$D28,D28), IF($E28=외피index!$B$8, 외피index!$C$8&"_"&COUNTIFS(E$2:$E28,외피index!$B$8,D$2:$D28,D28), IF($E28=외피index!$B$9, 외피index!$C$9&"_"&COUNTIFS(E$2:$E28,외피index!$B$9,D$2:$D28,D28), IF($E28=외피index!$B$10, 외피index!$C$10&"_"&COUNTIFS(E$2:$E28,외피index!$B$10,D$2:$D28,D28), 0)))))))),B28)),"") -> 1F_Zone003_SL_11 | B28: 1F_Zone003_SL_11 | C28: 1F | D28: 1F_Zone003 | E28: 층간바닥 | G28: 16.799957 | H28: 2F_Zone008 | I28: 수평 | J28: 180 | K28: 0 | L28: 0 | M28: 0 | N28: 0 | O28: 0 | P28: 0 | Q28: 0 | R28: 0 | S28: 0 | T28: 0 | U28: 0
A29: =IFERROR(IF(E29="","",IF(B29="",D29&"_"& IF($E29=외피index!$B$3, 외피index!$C$3&"_"&COUNTIFS(E$2:$E29,외피index!$B$3,D$2:$D29,D29), IF($E29=외피index!$B$4, 외피index!$C$4&"_"&COUNTIFS(E$2:$E29,외피index!$B$4,D$2:$D29,D29), IF($E29=외피index!$B$5, 외피index!$C$5&"_"&COUNTIFS(E$2:$E29,외피index!$B$5,D$2:$D29,D29), IF($E29=외피index!$B$6, 외피index!$C$6&"_"&COUNTIFS(E$2:$E29,외피index!$B$6,D$2:$D29,D29), IF($E29=외피index!$B$7, 외피index!$C$7&"_"&COUNTIFS(E$2:$E29,외피index!$B$7,D$2:$D29,D29), IF($E29=외피index!$B$8, 외피index!$C$8&"_"&COUNTIFS(E$2:$E29,외피index!$B$8,D$2:$D29,D29), IF($E29=외피index!$B$9, 외피index!$C$9&"_"&COUNTIFS(E$2:$E29,외피index!$B$9,D$2:$D29,D29), IF($E29=외피index!$B$10, 외피index!$C$10&"_"&COUNTIFS(E$2:$E29,외피index!$B$10,D$2:$D29,D29), 0)))))))),B29)),"") -> 1F_Zone004_SL_6 | B29: 1F_Zone004_SL_6 | C29: 1F | D29: 1F_Zone004 | E29: 층간바닥 | G29: 10.920057 | H29: 2F_Zone011 | I29: 수평 | J29: 180 | K29: 0 | L29: 0 | M29: 0 | N29: 0 | O29: 0 | P29: 0 | Q29: 0 | R29: 0 | S29: 0 | T29: 0 | U29: 0
A30: =IFERROR(IF(E30="","",IF(B30="",D30&"_"& IF($E30=외피index!$B$3, 외피index!$C$3&"_"&COUNTIFS(E$2:$E30,외피index!$B$3,D$2:$D30,D30), IF($E30=외피index!$B$4, 외피index!$C$4&"_"&COUNTIFS(E$2:$E30,외피index!$B$4,D$2:$D30,D30), IF($E30=외피index!$B$5, 외피index!$C$5&"_"&COUNTIFS(E$2:$E30,외피index!$B$5,D$2:$D30,D30), IF($E30=외피index!$B$6, 외피index!$C$6&"_"&COUNTIFS(E$2:$E30,외피index!$B$6,D$2:$D30,D30), IF($E30=외피index!$B$7, 외피index!$C$7&"_"&COUNTIFS(E$2:$E30,외피index!$B$7,D$2:$D30,D30), IF($E30=외피index!$B$8, 외피index!$C$8&"_"&COUNTIFS(E$2:$E30,외피index!$B$8,D$2:$D30,D30), IF($E30=외피index!$B$9, 외피index!$C$9&"_"&COUNTIFS(E$2:$E30,외피index!$B$9,D$2:$D30,D30), IF($E30=외피index!$B$10, 외피index!$C$10&"_"&COUNTIFS(E$2:$E30,외피index!$B$10,D$2:$D30,D30), 0)))))))),B30)),"") -> 1F_Zone003_SL_13 | B30: 1F_Zone003_SL_13 | C30: 1F | D30: 1F_Zone003 | E30: 층간바닥 | G30: 7.2799854 | H30: 2F_Zone011 | I30: 수평 | J30: 180 | K30: 0 | L30: 0 | M30: 0 | N30: 0 | O30: 0 | P30: 0 | Q30: 0 | R30: 0 | S30: 0 | T30: 0 | U30: 0
A31: =IFERROR(IF(E31="","",IF(B31="",D31&"_"& IF($E31=외피index!$B$3, 외피index!$C$3&"_"&COUNTIFS(E$2:$E31,외피index!$B$3,D$2:$D31,D31), IF($E31=외피index!$B$4, 외피index!$C$4&"_"&COUNTIFS(E$2:$E31,외피index!$B$4,D$2:$D31,D31), IF($E31=외피index!$B$5, 외피index!$C$5&"_"&COUNTIFS(E$2:$E31,외피index!$B$5,D$2:$D31,D31), IF($E31=외피index!$B$6, 외피index!$C$6&"_"&COUNTIFS(E$2:$E31,외피index!$B$6,D$2:$D31,D31), IF($E31=외피index!$B$7, 외피index!$C$7&"_"&COUNTIFS(E$2:$E31,외피index!$B$7,D$2:$D31,D31), IF($E31=외피index!$B$8, 외피index!$C$8&"_"&COUNTIFS(E$2:$E31,외피index!$B$8,D$2:$D31,D31), IF($E31=외피index!$B$9, 외피index!$C$9&"_"&COUNTIFS(E$2:$E31,외피index!$B$9,D$2:$D31,D31), IF($E31=외피index!$B$10, 외피index!$C$10&"_"&COUNTIFS(E$2:$E31,외피index!$B$10,D$2:$D31,D31), 0)))))))),B31)),"") -> 4F_Zone021_RF_5 | B31: 4F_Zone021_RF_5 | C31: 4F | D31: 4F_Zone021 | E31: 지붕 | G31: 16.799957 | I31: 수평 | J31: 0 | K31: 0 | L31: 0 | M31: 0 | N31: 0 | O31: 0 | P31: 0 | Q31: 0 | R31: 0 | S31: 0 | T31: 0 | U31: 0
A32: =IFERROR(IF(E32="","",IF(B32="",D32&"_"& IF($E32=외피index!$B$3, 외피index!$C$3&"_"&COUNTIFS(E$2:$E32,외피index!$B$3,D$2:$D32,D32), IF($E32=외피index!$B$4, 외피index!$C$4&"_"&COUNTIFS(E$2:$E32,외피index!$B$4,D$2:$D32,D32), IF($E32=외피index!$B$5, 외피index!$C$5&"_"&COUNTIFS(E$2:$E32,외피index!$B$5,D$2:$D32,D32), IF($E32=외피index!$B$6, 외피index!$C$6&"_"&COUNTIFS(E$2:$E32,외피index!$B$6,D$2:$D32,D32), IF($E32=외피index!$B$7, 외피index!$C$7&"_"&COUNTIFS(E$2:$E32,외피index!$B$7,D$2:$D32,D32), IF($E32=외피index!$B$8, 외피index!$C$8&"_"&COUNTIFS(E$2:$E32,외피index!$B$8,D$2:$D32,D32), IF($E32=외피index!$B$9, 외피index!$C$9&"_"&COUNTIFS(E$2:$E32,외피index!$B$9,D$2:$D32,D32), IF($E32=외피index!$B$10, 외피index!$C$10&"_"&COUNTIFS(E$2:$E32,외피index!$B$10,D$2:$D32,D32), 0)))))))),B32)),"") -> 1F_Zone005_RF_6 | B32: 1F_Zone005_RF_6 | C32: 1F | D32: 1F_Zone005 | E32: 지붕 | G32: 3.7170383 | I32: 수평 | J32: 0 | K32: 0 | L32: 0 | M32: 0 | N32: 0 | O32: 0 | P32: 0 | Q32: 0 | R32: 0 | S32: 0 | T32: 0 | U32: 0
A33: =IFERROR(IF(E33="","",IF(B33="",D33&"_"& IF($E33=외피index!$B$3, 외피index!$C$3&"_"&COUNTIFS(E$2:$E33,외피index!$B$3,D$2:$D33,D33), IF($E33=외피index!$B$4, 외피index!$C$4&"_"&COUNTIFS(E$2:$E33,외피index!$B$4,D$2:$D33,D33), IF($E33=외피index!$B$5, 외피index!$C$5&"_"&COUNTIFS(E$2:$E33,외피index!$B$5,D$2:$D33,D33), IF($E33=외피index!$B$6, 외피index!$C$6&"_"&COUNTIFS(E$2:$E33,외피index!$B$6,D$2:$D33,D33), IF($E33=외피index!$B$7, 외피index!$C$7&"_"&COUNTIFS(E$2:$E33,외피index!$B$7,D$2:$D33,D33), IF($E33=외피index!$B$8, 외피index!$C$8&"_"&COUNTIFS(E$2:$E33,외피index!$B$8,D$2:$D33,D33), IF($E33=외피index!$B$9, 외피index!$C$9&"_"&COUNTIFS(E$2:$E33,외피index!$B$9,D$2:$D33,D33), IF($E33=외피index!$B$10, 외피index!$C$10&"_"&COUNTIFS(E$2:$E33,외피index!$B$10,D$2:$D33,D33), 0)))))))),B33)),"") -> 3F_Zone014_SL_1 | B33: 3F_Zone014_SL_1 | C33: 3F | D33: 3F_Zone014 | E33: 층간바닥 | G33: 28.080031 | H33: 2F_Zone006 | I33: 수평 | J33: 180 | K33: 0 | L33: 0 | M33: 0 | N33: 0 | O33: 0 | P33: 0 | Q33: 0 | R33: 0 | S33: 0 | T33: 0 | U33: 0
A34: =IFERROR(IF(E34="","",IF(B34="",D34&"_"& IF($E34=외피index!$B$3, 외피index!$C$3&"_"&COUNTIFS(E$2:$E34,외피index!$B$3,D$2:$D34,D34), IF($E34=외피index!$B$4, 외피index!$C$4&"_"&COUNTIFS(E$2:$E34,외피index!$B$4,D$2:$D34,D34), IF($E34=외피index!$B$5, 외피index!$C$5&"_"&COUNTIFS(E$2:$E34,외피index!$B$5,D$2:$D34,D34), IF($E34=외피index!$B$6, 외피index!$C$6&"_"&COUNTIFS(E$2:$E34,외피index!$B$6,D$2:$D34,D34), IF($E34=외피index!$B$7, 외피index!$C$7&"_"&COUNTIFS(E$2:$E34,외피index!$B$7,D$2:$D34,D34), IF($E34=외피index!$B$8, 외피index!$C$8&"_"&COUNTIFS(E$2:$E34,외피index!$B$8,D$2:$D34,D34), IF($E34=외피index!$B$9, 외피index!$C$9&"_"&COUNTIFS(E$2:$E34,외피index!$B$9,D$2:$D34,D34), IF($E34=외피index!$B$10, 외피index!$C$10&"_"&COUNTIFS(E$2:$E34,외피index!$B$10,D$2:$D34,D34), 0)))))))),B34)),"") -> 3F_Zone015_SL_1 | B34: 3F_Zone015_SL_1 | C34: 3F | D34: 3F_Zone015 | E34: 층간바닥 | G34: 22.879955 | H34: 2F_Zone007 | I34: 수평 | J34: 180 | K34: 0 | L34: 0 | M34: 0 | N34: 0 | O34: 0 | P34: 0 | Q34: 0 | R34: 0 | S34: 0 | T34: 0 | U34: 0
A35: =IFERROR(IF(E35="","",IF(B35="",D35&"_"& IF($E35=외피index!$B$3, 외피index!$C$3&"_"&COUNTIFS(E$2:$E35,외피index!$B$3,D$2:$D35,D35), IF($E35=외피index!$B$4, 외피index!$C$4&"_"&COUNTIFS(E$2:$E35,외피index!$B$4,D$2:$D35,D35), IF($E35=외피index!$B$5, 외피index!$C$5&"_"&COUNTIFS(E$2:$E35,외피index!$B$5,D$2:$D35,D35), IF($E35=외피index!$B$6, 외피index!$C$6&"_"&COUNTIFS(E$2:$E35,외피index!$B$6,D$2:$D35,D35), IF($E35=외피index!$B$7, 외피index!$C$7&"_"&COUNTIFS(E$2:$E35,외피index!$B$7,D$2:$D35,D35), IF($E35=외피index!$B$8, 외피index!$C$8&"_"&COUNTIFS(E$2:$E35,외피index!$B$8,D$2:$D35,D35), IF($E35=외피index!$B$9, 외피index!$C$9&"_"&COUNTIFS(E$2:$E35,외피index!$B$9,D$2:$D35,D35), IF($E35=외피index!$B$10, 외피index!$C$10&"_"&COUNTIFS(E$2:$E35,외피index!$B$10,D$2:$D35,D35), 0)))))))),B35)),"") -> 3F_Zone016_SL_1 | B35: 3F_Zone016_SL_1 | C35: 3F | D35: 3F_Zone016 | E35: 층간바닥 | G35: 15.449966 | H35: 2F_Zone008 | I35: 수평 | J35: 0 | K35: 0 | L35: 0 | M35: 0 | N35: 0 | O35: 0 | P35: 0 | Q35: 0 | R35: 0 | S35: 0 | T35: 0 | U35: 0
A36: =IFERROR(IF(E36="","",IF(B36="",D36&"_"& IF($E36=외피index!$B$3, 외피index!$C$3&"_"&COUNTIFS(E$2:$E36,외피index!$B$3,D$2:$D36,D36), IF($E36=외피index!$B$4, 외피index!$C$4&"_"&COUNTIFS(E$2:$E36,외피index!$B$4,D$2:$D36,D36), IF($E36=외피index!$B$5, 외피index!$C$5&"_"&COUNTIFS(E$2:$E36,외피index!$B$5,D$2:$D36,D36), IF($E36=외피index!$B$6, 외피index!$C$6&"_"&COUNTIFS(E$2:$E36,외피index!$B$6,D$2:$D36,D36), IF($E36=외피index!$B$7, 외피index!$C$7&"_"&COUNTIFS(E$2:$E36,외피index!$B$7,D$2:$D36,D36), IF($E36=외피index!$B$8, 외피index!$C$8&"_"&COUNTIFS(E$2:$E36,외피index!$B$8,D$2:$D36,D36), IF($E36=외피index!$B$9, 외피index!$C$9&"_"&COUNTIFS(E$2:$E36,외피index!$B$9,D$2:$D36,D36), IF($E36=외피index!$B$10, 외피index!$C$10&"_"&COUNTIFS(E$2:$E36,외피index!$B$10,D$2:$D36,D36), 0)))))))),B36)),"") -> 3F_Zone015_SL_2 | B36: 3F_Zone015_SL_2 | C36: 3F | D36: 3F_Zone015 | E36: 층간바닥 | G36: 14.040055 | H36: 2F_Zone009 | I36: 수평 | J36: 180 | K36: 0 | L36: 0 | M36: 0 | N36: 0 | O36: 0 | P36: 0 | Q36: 0 | R36: 0 | S36: 0 | T36: 0 | U36: 0
A37: =IFERROR(IF(E37="","",IF(B37="",D37&"_"& IF($E37=외피index!$B$3, 외피index!$C$3&"_"&COUNTIFS(E$2:$E37,외피index!$B$3,D$2:$D37,D37), IF($E37=외피index!$B$4, 외피index!$C$4&"_"&COUNTIFS(E$2:$E37,외피index!$B$4,D$2:$D37,D37), IF($E37=외피index!$B$5, 외피index!$C$5&"_"&COUNTIFS(E$2:$E37,외피index!$B$5,D$2:$D37,D37), IF($E37=외피index!$B$6, 외피index!$C$6&"_"&COUNTIFS(E$2:$E37,외피index!$B$6,D$2:$D37,D37), IF($E37=외피index!$B$7, 외피index!$C$7&"_"&COUNTIFS(E$2:$E37,외피index!$B$7,D$2:$D37,D37), IF($E37=외피index!$B$8, 외피index!$C$8&"_"&COUNTIFS(E$2:$E37,외피index!$B$8,D$2:$D37,D37), IF($E37=외피index!$B$9, 외피index!$C$9&"_"&COUNTIFS(E$2:$E37,외피index!$B$9,D$2:$D37,D37), IF($E37=외피index!$B$10, 외피index!$C$10&"_"&COUNTIFS(E$2:$E37,외피index!$B$10,D$2:$D37,D37), 0)))))))),B37)),"") -> 3F_Zone017_SL_1 | B37: 3F_Zone017_SL_1 | C37: 3F | D37: 3F_Zone017 | E37: 층간바닥 | G37: 8.6799365 | H37: 2F_Zone006 | I37: 수평 | J37: 180 | K37: 0 | L37: 0 | M37: 0 | N37: 0 | O37: 0 | P37: 0 | Q37: 0 | R37: 0 | S37: 0 | T37: 0 | U37: 0
A38: =IFERROR(IF(E38="","",IF(B38="",D38&"_"& IF($E38=외피index!$B$3, 외피index!$C$3&"_"&COUNTIFS(E$2:$E38,외피index!$B$3,D$2:$D38,D38), IF($E38=외피index!$B$4, 외피index!$C$4&"_"&COUNTIFS(E$2:$E38,외피index!$B$4,D$2:$D38,D38), IF($E38=외피index!$B$5, 외피index!$C$5&"_"&COUNTIFS(E$2:$E38,외피index!$B$5,D$2:$D38,D38), IF($E38=외피index!$B$6, 외피index!$C$6&"_"&COUNTIFS(E$2:$E38,외피index!$B$6,D$2:$D38,D38), IF($E38=외피index!$B$7, 외피index!$C$7&"_"&COUNTIFS(E$2:$E38,외피index!$B$7,D$2:$D38,D38), IF($E38=외피index!$B$8, 외피index!$C$8&"_"&COUNTIFS(E$2:$E38,외피index!$B$8,D$2:$D38,D38), IF($E38=외피index!$B$9, 외피index!$C$9&"_"&COUNTIFS(E$2:$E38,외피index!$B$9,D$2:$D38,D38), IF($E38=외피index!$B$10, 외피index!$C$10&"_"&COUNTIFS(E$2:$E38,외피index!$B$10,D$2:$D38,D38), 0)))))))),B38)),"") -> 3F_Zone016_SL_11 | B38: 3F_Zone016_SL_11 | C38: 3F | D38: 3F_Zone016 | E38: 층간바닥 | G38: 5.8799915 | H38: 2F_Zone006 | I38: 수평 | J38: 0 | K38: 0 | L38: 0 | M38: 0 | N38: 0 | O38: 0 | P38: 0 | Q38: 0 | R38: 0 | S38: 0 | T38: 0 | U38: 0
A39: =IFERROR(IF(E39="","",IF(B39="",D39&"_"& IF($E39=외피index!$B$3, 외피index!$C$3&"_"&COUNTIFS(E$2:$E39,외피index!$B$3,D$2:$D39,D39), IF($E39=외피index!$B$4, 외피index!$C$4&"_"&COUNTIFS(E$2:$E39,외피index!$B$4,D$2:$D39,D39), IF($E39=외피index!$B$5, 외피index!$C$5&"_"&COUNTIFS(E$2:$E39,외피index!$B$5,D$2:$D39,D39), IF($E39=외피index!$B$6, 외피index!$C$6&"_"&COUNTIFS(E$2:$E39,외피index!$B$6,D$2:$D39,D39), IF($E39=외피index!$B$7, 외피index!$C$7&"_"&COUNTIFS(E$2:$E39,외피index!$B$7,D$2:$D39,D39), IF($E39=외피index!$B$8, 외피index!$C$8&"_"&COUNTIFS(E$2:$E39,외피index!$B$8,D$2:$D39,D39), IF($E39=외피index!$B$9, 외피index!$C$9&"_"&COUNTIFS(E$2:$E39,외피index!$B$9,D$2:$D39,D39), IF($E39=외피index!$B$10, 외피index!$C$10&"_"&COUNTIFS(E$2:$E39,외피index!$B$10,D$2:$D39,D39), 0)))))))),B39)),"") -> 3F_Zone019_SL_2 | B39: 3F_Zone019_SL_2 | C39: 3F | D39: 3F_Zone019 | E39: 층간바닥 | G39: 5.5822345 | H39: 2F_Zone008 | I39: 수평 | J39: 0 | K39: 0 | L39: 0 | M39: 0 | N39: 0 | O39: 0 | P39: 0 | Q39: 0 | R39: 0 | S39: 0 | T39: 0 | U39: 0
A40: =IFERROR(IF(E40="","",IF(B40="",D40&"_"& IF($E40=외피index!$B$3, 외피index!$C$3&"_"&COUNTIFS(E$2:$E40,외피index!$B$3,D$2:$D40,D40), IF($E40=외피index!$B$4, 외피index!$C$4&"_"&COUNTIFS(E$2:$E40,외피index!$B$4,D$2:$D40,D40), IF($E40=외피index!$B$5, 외피index!$C$5&"_"&COUNTIFS(E$2:$E40,외피index!$B$5,D$2:$D40,D40), IF($E40=외피index!$B$6, 외피index!$C$6&"_"&COUNTIFS(E$2:$E40,외피index!$B$6,D$2:$D40,D40), IF($E40=외피index!$B$7, 외피index!$C$7&"_"&COUNTIFS(E$2:$E40,외피index!$B$7,D$2:$D40,D40), IF($E40=외피index!$B$8, 외피index!$C$8&"_"&COUNTIFS(E$2:$E40,외피index!$B$8,D$2:$D40,D40), IF($E40=외피index!$B$9, 외피index!$C$9&"_"&COUNTIFS(E$2:$E40,외피index!$B$9,D$2:$D40,D40), IF($E40=외피index!$B$10, 외피index!$C$10&"_"&COUNTIFS(E$2:$E40,외피index!$B$10,D$2:$D40,D40), 0)))))))),B40)),"") -> 3F_Zone020_SL_3 | B40: 3F_Zone020_SL_3 | C40: 3F | D40: 3F_Zone020 | E40: 층간바닥 | G40: 4.7999878 | H40: 2F_Zone013 | I40: 수평 | J40: 180 | K40: 0 | L40: 0 | M40: 0 | N40: 0 | O40: 0 | P40: 0 | Q40: 0 | R40: 0 | S40: 0 | T40: 0 | U40: 0
...

Sheet ThermalBridge_3D
A1: 번호 | B1: 구분1 | C1: 구분2 | D1: 열교항목 | E1: 열교길이
A2: =IF(D2="","",INDEX(외피index!$C$75:$C$87,MATCH(D2,외피index!$B$75:$B$87,0),1)&"_"& IF(D2=외피index!$B$75,COUNTIF($D$2:D2,외피index!$B$75), IF(D2=외피index!$B$76,COUNTIF($D$2:D2,외피index!$B$76), IF(D2=외피index!$B$77,COUNTIF($D$2:D2,외피index!$B$77), IF(D2=외피index!$B$78,COUNTIF($D$2:D2,외피index!$B$78), IF(D2=외피index!$B$79,COUNTIF($D$2:D2,외피index!$B$79), IF(D2=외피index!$B$80,COUNTIF($D$2:D2,외피index!$B$80), IF(D2=외피index!$B$82,COUNTIF($D$2:D2,외피index!$B$82), IF(D2=외피index!$B$83,COUNTIF($D$2:D2,외피index!$B$83), IF(D2=외피index!$B$84,COUNTIF($D$2:D2,외피index!$B$84), IF(D2=외피index!$B$85,COUNTIF($D$2:D2,외피index!$B$85), IF(D2=외피index!$B$86,COUNTIF($D$2:D2,외피index!$B$86), IF(D2=외피index!$B$87,COUNTIF($D$2:D2,외피index!$B$87)))))))))))))) -> RTB1_1 | B2: 지붕 | C2: 평지붕 | D2: 평지붕+외벽[90] | E2: 168.09
A3: =IF(D3="","",INDEX(외피index!$C$75:$C$87,MATCH(D3,외피index!$B$75:$B$87,0),1)&"_"& IF(D3=외피index!$B$75,COUNTIF($D$2:D3,외피index!$B$75), IF(D3=외피index!$B$76,COUNTIF($D$2:D3,외피index!$B$76), IF(D3=외피index!$B$77,COUNTIF($D$2:D3,외피index!$B$77), IF(D3=외피index!$B$78,COUNTIF($D$2:D3,외피index!$B$78), IF(D3=외피index!$B$79,COUNTIF($D$2:D3,외피index!$B$79), IF(D3=외피index!$B$80,COUNTIF($D$2:D3,외피index!$B$80), IF(D3=외피index!$B$82,COUNTIF($D$2:D3,외피index!$B$82), IF(D3=외피index!$B$83,COUNTIF($D$2:D3,외피index!$B$83), IF(D3=외피index!$B$84,COUNTIF($D$2:D3,외피index!$B$84), IF(D3=외피index!$B$85,COUNTIF($D$2:D3,외피index!$B$85), IF(D3=외피index!$B$86,COUNTIF($D$2:D3,외피index!$B$86), IF(D3=외피index!$B$87,COUNTIF($D$2:D3,외피index!$B$87)))))))))))))) -> RTB3_1 | B3: 지붕 | C3: 평지붕 | D3: 평지붕+내벽 | E3: 41.25
A4: =IF(D4="","",INDEX(외피index!$C$75:$C$87,MATCH(D4,외피index!$B$75:$B$87,0),1)&"_"& IF(D4=외피index!$B$75,COUNTIF($D$2:D4,외피index!$B$75), IF(D4=외피index!$B$76,COUNTIF($D$2:D4,외피index!$B$76), IF(D4=외피index!$B$77,COUNTIF($D$2:D4,외피index!$B$77), IF(D4=외피index!$B$78,COUNTIF($D$2:D4,외피index!$B$78), IF(D4=외피index!$B$79,COUNTIF($D$2:D4,외피index!$B$79), IF(D4=외피index!$B$80,COUNTIF($D$2:D4,외피index!$B$80), IF(D4=외피index!$B$82,COUNTIF($D$2:D4,외피index!$B$82), IF(D4=외피index!$B$83,COUNTIF($D$2:D4,외피index!$B$83), IF(D4=외피index!$B$84,COUNTIF($D$2:D4,외피index!$B$84), IF(D4=외피index!$B$85,COUNTIF($D$2:D4,외피index!$B$85), IF(D4=외피index!$B$86,COUNTIF($D$2:D4,외피index!$B$86), IF(D4=외피index!$B$87,COUNTIF($D$2:D4,외피index!$B$87)))))))))))))) -> RTB4_1 | B4: 지붕 | C4: 경사지붕 | D4: 경사지붕 | E4: 0
A5: =IF(D5="","",INDEX(외피index!$C$75:$C$87,MATCH(D5,외피index!$B$75:$B$87,0),1)&"_"& IF(D5=외피index!$B$75,COUNTIF($D$2:D5,외피index!$B$75), IF(D5=외피index!$B$76,COUNTIF($D$2:D5,외피index!$B$76), IF(D5=외피index!$B$77,COUNTIF($D$2:D5,외피index!$B$77), IF(D5=외피index!$B$78,COUNTIF($D$2:D5,외피index!$B$78), IF(D5=외피index!$B$79,COUNTIF($D$2:D5,외피index!$B$79), IF(D5=외피index!$B$80,COUNTIF($D$2:D5,외피index!$B$80), IF(D5=외피index!$B$82,COUNTIF($D$2:D5,외피index!$B$82), IF(D5=외피index!$B$83,COUNTIF($D$2:D5,외피index!$B$83), IF(D5=외피index!$B$84,COUNTIF($D$2:D5,외피index!$B$84), IF(D5=외피index!$B$85,COUNTIF($D$2:D5,외피index!$B$85), IF(D5=외피index!$B$86,COUNTIF($D$2:D5,외피index!$B$86), IF(D5=외피index!$B$87,COUNTIF($D$2:D5,외피index!$B$87)))))))))))))) -> #N/A | D5: 경사지붕+벽 | E5: 0
A6: =IF(D6="","",INDEX(외피index!$C$75:$C$87,MATCH(D6,외피index!$B$75:$B$87,0),1)&"_"& IF(D6=외피index!$B$75,COUNTIF($D$2:D6,외피index!$B$75), IF(D6=외피index!$B$76,COUNTIF($D$2:D6,외피index!$B$76), IF(D6=외피index!$B$77,COUNTIF($D$2:D6,외피index!$B$77), IF(D6=외피index!$B$78,COUNTIF($D$2:D6,외피index!$B$78), IF(D6=외피index!$B$79,COUNTIF($D$2:D6,외피index!$B$79), IF(D6=외피index!$B$80,COUNTIF($D$2:D6,외피index!$B$80), IF(D6=외피index!$B$82,COUNTIF($D$2:D6,외피index!$B$82), IF(D6=외피index!$B$83,COUNTIF($D$2:D6,외피index!$B$83), IF(D6=외피index!$B$84,COUNTIF($D$2:D6,외피index!$B$84), IF(D6=외피index!$B$85,COUNTIF($D$2:D6,외피index!$B$85), IF(D6=외피index!$B$86,COUNTIF($D$2:D6,외피index!$B$86), IF(D6=외피index!$B$87,COUNTIF($D$2:D6,외피index!$B$87)))))))))))))) -> #N/A | D6: 경사지붕+경사벽 | E6: 0
A7: =IF(D7="","",INDEX(외피index!$C$75:$C$87,MATCH(D7,외피index!$B$75:$B$87,0),1)&"_"& IF(D7=외피index!$B$75,COUNTIF($D$2:D7,외피index!$B$75), IF(D7=외피index!$B$76,COUNTIF($D$2:D7,외피index!$B$76), IF(D7=외피index!$B$77,COUNTIF($D$2:D7,외피index!$B$77), IF(D7=외피index!$B$78,COUNTIF($D$2:D7,외피index!$B$78), IF(D7=외피index!$B$79,COUNTIF($D$2:D7,외피index!$B$79), IF(D7=외피index!$B$80,COUNTIF($D$2:D7,외피index!$B$80), IF(D7=외피index!$B$82,COUNTIF($D$2:D7,외피index!$B$82), IF(D7=외피index!$B$83,COUNTIF($D$2:D7,외피index!$B$83), IF(D7=외피index!$B$84,COUNTIF($D$2:D7,외피index!$B$84), IF(D7=외피index!$B$85,COUNTIF($D$2:D7,외피index!$B$85), IF(D7=외피index!$B$86,COUNTIF($D$2:D7,외피index!$B$86), IF(D7=외피index!$B$87,COUNTIF($D$2:D7,외피index!$B$87)))))))))))))) -> #N/A | D7: 슬라브+벽 | E7: 67.7
A8: =IF(D8="","",INDEX(외피index!$C$75:$C$87,MATCH(D8,외피index!$B$75:$B$87,0),1)&"_"& IF(D8=외피index!$B$75,COUNTIF($D$2:D8,외피index!$B$75), IF(D8=외피index!$B$76,COUNTIF($D$2:D8,외피index!$B$76), IF(D8=외피index!$B$77,COUNTIF($D$2:D8,외피index!$B$77), IF(D8=외피index!$B$78,COUNTIF($D$2:D8,외피index!$B$78), IF(D8=외피index!$B$79,COUNTIF($D$2:D8,외피index!$B$79), IF(D8=외피index!$B$80,COUNTIF($D$2:D8,외피index!$B$80), IF(D8=외피index!$B$82,COUNTIF($D$2:D8,외피index!$B$82), IF(D8=외피index!$B$83,COUNTIF($D$2:D8,외피index!$B$83), IF(D8=외피index!$B$84,COUNTIF($D$2:D8,외피index!$B$84), IF(D8=외피index!$B$85,COUNTIF($D$2:D8,외피index!$B$85), IF(D8=외피index!$B$86,COUNTIF($D$2:D8,외피index!$B$86), IF(D8=외피index!$B$87,COUNTIF($D$2:D8,외피index!$B$87)))))))))))))) -> #N/A | D8: 내벽+외벽 | E8: 54.8
A9: =IF(D9="","",INDEX(외피index!$C$75:$C$87,MATCH(D9,외피index!$B$75:$B$87,0),1)&"_"& IF(D9=외피index!$B$75,COUNTIF($D$2:D9,외피index!$B$75), IF(D9=외피index!$B$76,COUNTIF($D$2:D9,외피index!$B$76), IF(D9=외피index!$B$77,COUNTIF($D$2:D9,외피index!$B$77), IF(D9=외피index!$B$78,COUNTIF($D$2:D9,외피index!$B$78), IF(D9=외피index!$B$79,COUNTIF($D$2:D9,외피index!$B$79), IF(D9=외피index!$B$80,COUNTIF($D$2:D9,외피index!$B$80), IF(D9=외피index!$B$82,COUNTIF($D$2:D9,외피index!$B$82), IF(D9=외피index!$B$83,COUNTIF($D$2:D9,외피index!$B$83), IF(D9=외피index!$B$84,COUNTIF($D$2:D9,외피index!$B$84), IF(D9=외피index!$B$85,COUNTIF($D$2:D9,외피index!$B$85), IF(D9=외피index!$B$86,COUNTIF($D$2:D9,외피index!$B$86), IF(D9=외피index!$B$87,COUNTIF($D$2:D9,외피index!$B$87)))))))))))))) -> #N/A | D9: 외벽+외벽 | E9: 144.33
A10: =IF(D10="","",INDEX(외피index!$C$75:$C$87,MATCH(D10,외피index!$B$75:$B$87,0),1)&"_"& IF(D10=외피index!$B$75,COUNTIF($D$2:D10,외피index!$B$75), IF(D10=외피index!$B$76,COUNTIF($D$2:D10,외피index!$B$76), IF(D10=외피index!$B$77,COUNTIF($D$2:D10,외피index!$B$77), IF(D10=외피index!$B$78,COUNTIF($D$2:D10,외피index!$B$78), IF(D10=외피index!$B$79,COUNTIF($D$2:D10,외피index!$B$79), IF(D10=외피index!$B$80,COUNTIF($D$2:D10,외피index!$B$80), IF(D10=외피index!$B$82,COUNTIF($D$2:D10,외피index!$B$82), IF(D10=외피index!$B$83,COUNTIF($D$2:D10,외피index!$B$83), IF(D10=외피index!$B$84,COUNTIF($D$2:D10,외피index!$B$84), IF(D10=외피index!$B$85,COUNTIF($D$2:D10,외피index!$B$85), IF(D10=외피index!$B$86,COUNTIF($D$2:D10,외피index!$B$86), IF(D10=외피index!$B$87,COUNTIF($D$2:D10,외피index!$B$87)))))))))))))) -> #N/A | D10: 외벽+내벽+외벽 | E10: 18.2
A11: =IF(D11="","",INDEX(외피index!$C$75:$C$87,MATCH(D11,외피index!$B$75:$B$87,0),1)&"_"& IF(D11=외피index!$B$75,COUNTIF($D$2:D11,외피index!$B$75), IF(D11=외피index!$B$76,COUNTIF($D$2:D11,외피index!$B$76), IF(D11=외피index!$B$77,COUNTIF($D$2:D11,외피index!$B$77), IF(D11=외피index!$B$78,COUNTIF($D$2:D11,외피index!$B$78), IF(D11=외피index!$B$79,COUNTIF($D$2:D11,외피index!$B$79), IF(D11=외피index!$B$80,COUNTIF($D$2:D11,외피index!$B$80), IF(D11=외피index!$B$82,COUNTIF($D$2:D11,외피index!$B$82), IF(D11=외피index!$B$83,COUNTIF($D$2:D11,외피index!$B$83), IF(D11=외피index!$B$84,COUNTIF($D$2:D11,외피index!$B$84), IF(D11=외피index!$B$85,COUNTIF($D$2:D11,외피index!$B$85), IF(D11=외피index!$B$86,COUNTIF($D$2:D11,외피index!$B$86), IF(D11=외피index!$B$87,COUNTIF($D$2:D11,외피index!$B$87)))))))))))))) -> #N/A | D11: --- | E11: 244.18
A12: =IF(D12="","",INDEX(외피index!$C$75:$C$87,MATCH(D12,외피index!$B$75:$B$87,0),1)&"_"& IF(D12=외피index!$B$75,COUNTIF($D$2:D12,외피index!$B$75), IF(D12=외피index!$B$76,COUNTIF($D$2:D12,외피index!$B$76), IF(D12=외피index!$B$77,COUNTIF($D$2:D12,외피index!$B$77), IF(D12=외피index!$B$78,COUNTIF($D$2:D12,외피index!$B$78), IF(D12=외피index!$B$79,COUNTIF($D$2:D12,외피index!$B$79), IF(D12=외피index!$B$80,COUNTIF($D$2:D12,외피index!$B$80), IF(D12=외피index!$B$82,COUNTIF($D$2:D12,외피index!$B$82), IF(D12=외피index!$B$83,COUNTIF($D$2:D12,외피index!$B$83), IF(D12=외피index!$B$84,COUNTIF($D$2:D12,외피index!$B$84), IF(D12=외피index!$B$85,COUNTIF($D$2:D12,외피index!$B$85), IF(D12=외피index!$B$86,COUNTIF($D$2:D12,외피index!$B$86), IF(D12=외피index!$B$87,COUNTIF($D$2:D12,외피index!$B$87)))))))))))))) -> #N/A | D12: 평지붕+벽[270] | E12: 9.25
A13: =IF(D13="","",INDEX(외피index!$C$75:$C$87,MATCH(D13,외피index!$B$75:$B$87,0),1)&"_"& IF(D13=외피index!$B$75,COUNTIF($D$2:D13,외피index!$B$75), IF(D13=외피index!$B$76,COUNTIF($D$2:D13,외피index!$B$76), IF(D13=외피index!$B$77,COUNTIF($D$2:D13,외피index!$B$77), IF(D13=외피index!$B$78,COUNTIF($D$2:D13,외피index!$B$78), IF(D13=외피index!$B$79,COUNTIF($D$2:D13,외피index!$B$79), IF(D13=외피index!$B$80,COUNTIF($D$2:D13,외피index!$B$80), IF(D13=외피index!$B$82,COUNTIF($D$2:D13,외피index!$B$82), IF(D13=외피index!$B$83,COUNTIF($D$2:D13,외피index!$B$83), IF(D13=외피index!$B$84,COUNTIF($D$2:D13,외피index!$B$84), IF(D13=외피index!$B$85,COUNTIF($D$2:D13,외피index!$B$85), IF(D13=외피index!$B$86,COUNTIF($D$2:D13,외피index!$B$86), IF(D13=외피index!$B$87,COUNTIF($D$2:D13,외피index!$B$87)))))))))))))) -> #N/A | D13: 평지붕+벽[270]+내벽 | E13: 14.25
A14: =IF(D14="","",INDEX(외피index!$C$75:$C$87,MATCH(D14,외피index!$B$75:$B$87,0),1)&"_"& IF(D14=외피index!$B$75,COUNTIF($D$2:D14,외피index!$B$75), IF(D14=외피index!$B$76,COUNTIF($D$2:D14,외피index!$B$76), IF(D14=외피index!$B$77,COUNTIF($D$2:D14,외피index!$B$77), IF(D14=외피index!$B$78,COUNTIF($D$2:D14,외피index!$B$78), IF(D14=외피index!$B$79,COUNTIF($D$2:D14,외피index!$B$79), IF(D14=외피index!$B$80,COUNTIF($D$2:D14,외피index!$B$80), IF(D14=외피index!$B$82,COUNTIF($D$2:D14,외피index!$B$82), IF(D14=외피index!$B$83,COUNTIF($D$2:D14,외피index!$B$83), IF(D14=외피index!$B$84,COUNTIF($D$2:D14,외피index!$B$84), IF(D14=외피index!$B$85,COUNTIF($D$2:D14,외피index!$B$85), IF(D14=외피index!$B$86,COUNTIF($D$2:D14,외피index!$B$86), IF(D14=외피index!$B$87,COUNTIF($D$2:D14,외피index!$B$87))))))))))))))
A15: =IF(D15="","",INDEX(외피index!$C$75:$C$87,MATCH(D15,외피index!$B$75:$B$87,0),1)&"_"& IF(D15=외피index!$B$75,COUNTIF($D$2:D15,외피index!$B$75), IF(D15=외피index!$B$76,COUNTIF($D$2:D15,외피index!$B$76), IF(D15=외피index!$B$77,COUNTIF($D$2:D15,외피index!$B$77), IF(D15=외피index!$B$78,COUNTIF($D$2:D15,외피index!$B$78), IF(D15=외피index!$B$79,COUNTIF($D$2:D15,외피index!$B$79), IF(D15=외피index!$B$80,COUNTIF($D$2:D15,외피index!$B$80), IF(D15=외피index!$B$82,COUNTIF($D$2:D15,외피index!$B$82), IF(D15=외피index!$B$83,COUNTIF($D$2:D15,외피index!$B$83), IF(D15=외피index!$B$84,COUNTIF($D$2:D15,외피index!$B$84), IF(D15=외피index!$B$85,COUNTIF($D$2:D15,외피index!$B$85), IF(D15=외피index!$B$86,COUNTIF($D$2:D15,외피index!$B$86), IF(D15=외피index!$B$87,COUNTIF($D$2:D15,외피index!$B$87))))))))))))))
A16: =IF(D16="","",INDEX(외피index!$C$75:$C$87,MATCH(D16,외피index!$B$75:$B$87,0),1)&"_"& IF(D16=외피index!$B$75,COUNTIF($D$2:D16,외피index!$B$75), IF(D16=외피index!$B$76,COUNTIF($D$2:D16,외피index!$B$76), IF(D16=외피index!$B$77,COUNTIF($D$2:D16,외피index!$B$77), IF(D16=외피index!$B$78,COUNTIF($D$2:D16,외피index!$B$78), IF(D16=외피index!$B$79,COUNTIF($D$2:D16,외피index!$B$79), IF(D16=외피index!$B$80,COUNTIF($D$2:D16,외피index!$B$80), IF(D16=외피index!$B$82,COUNTIF($D$2:D16,외피index!$B$82), IF(D16=외피index!$B$83,COUNTIF($D$2:D16,외피index!$B$83), IF(D16=외피index!$B$84,COUNTIF($D$2:D16,외피index!$B$84), IF(D16=외피index!$B$85,COUNTIF($D$2:D16,외피index!$B$85), IF(D16=외피index!$B$86,COUNTIF($D$2:D16,외피index!$B$86), IF(D16=외피index!$B$87,COUNTIF($D$2:D16,외피index!$B$87))))))))))))))
A17: =IF(D17="","",INDEX(외피index!$C$75:$C$87,MATCH(D17,외피index!$B$75:$B$87,0),1)&"_"& IF(D17=외피index!$B$75,COUNTIF($D$2:D17,외피index!$B$75), IF(D17=외피index!$B$76,COUNTIF($D$2:D17,외피index!$B$76), IF(D17=외피index!$B$77,COUNTIF($D$2:D17,외피index!$B$77), IF(D17=외피index!$B$78,COUNTIF($D$2:D17,외피index!$B$78), IF(D17=외피index!$B$79,COUNTIF($D$2:D17,외피index!$B$79), IF(D17=외피index!$B$80,COUNTIF($D$2:D17,외피index!$B$80), IF(D17=외피index!$B$82,COUNTIF($D$2:D17,외피index!$B$82), IF(D17=외피index!$B$83,COUNTIF($D$2:D17,외피index!$B$83), IF(D17=외피index!$B$84,COUNTIF($D$2:D17,외피index!$B$84), IF(D17=외피index!$B$85,COUNTIF($D$2:D17,외피index!$B$85), IF(D17=외피index!$B$86,COUNTIF($D$2:D17,외피index!$B$86), IF(D17=외피index!$B$87,COUNTIF($D$2:D17,외피index!$B$87))))))))))))))
A18: =IF(D18="","",INDEX(외피index!$C$75:$C$87,MATCH(D18,외피index!$B$75:$B$87,0),1)&"_"& IF(D18=외피index!$B$75,COUNTIF($D$2:D18,외피index!$B$75), IF(D18=외피index!$B$76,COUNTIF($D$2:D18,외피index!$B$76), IF(D18=외피index!$B$77,COUNTIF($D$2:D18,외피index!$B$77), IF(D18=외피index!$B$78,COUNTIF($D$2:D18,외피index!$B$78), IF(D18=외피index!$B$79,COUNTIF($D$2:D18,외피index!$B$79), IF(D18=외피index!$B$80,COUNTIF($D$2:D18,외피index!$B$80), IF(D18=외피index!$B$82,COUNTIF($D$2:D18,외피index!$B$82), IF(D18=외피index!$B$83,COUNTIF($D$2:D18,외피index!$B$83), IF(D18=외피index!$B$84,COUNTIF($D$2:D18,외피index!$B$84), IF(D18=외피index!$B$85,COUNTIF($D$2:D18,외피index!$B$85), IF(D18=외피index!$B$86,COUNTIF($D$2:D18,외피index!$B$86), IF(D18=외피index!$B$87,COUNTIF($D$2:D18,외피index!$B$87))))))))))))))
A19: =IF(D19="","",INDEX(외피index!$C$75:$C$87,MATCH(D19,외피index!$B$75:$B$87,0),1)&"_"& IF(D19=외피index!$B$75,COUNTIF($D$2:D19,외피index!$B$75), IF(D19=외피index!$B$76,COUNTIF($D$2:D19,외피index!$B$76), IF(D19=외피index!$B$77,COUNTIF($D$2:D19,외피index!$B$77), IF(D19=외피index!$B$78,COUNTIF($D$2:D19,외피index!$B$78), IF(D19=외피index!$B$79,COUNTIF($D$2:D19,외피index!$B$79), IF(D19=외피index!$B$80,COUNTIF($D$2:D19,외피index!$B$80), IF(D19=외피index!$B$82,COUNTIF($D$2:D19,외피index!$B$82), IF(D19=외피index!$B$83,COUNTIF($D$2:D19,외피index!$B$83), IF(D19=외피index!$B$84,COUNTIF($D$2:D19,외피index!$B$84), IF(D19=외피index!$B$85,COUNTIF($D$2:D19,외피index!$B$85), IF(D19=외피index!$B$86,COUNTIF($D$2:D19,외피index!$B$86), IF(D19=외피index!$B$87,COUNTIF($D$2:D19,외피index!$B$87))))))))))))))
A20: =IF(D20="","",INDEX(외피index!$C$75:$C$87,MATCH(D20,외피index!$B$75:$B$87,0),1)&"_"& IF(D20=외피index!$B$75,COUNTIF($D$2:D20,외피index!$B$75), IF(D20=외피index!$B$76,COUNTIF($D$2:D20,외피index!$B$76), IF(D20=외피index!$B$77,COUNTIF($D$2:D20,외피index!$B$77), IF(D20=외피index!$B$78,COUNTIF($D$2:D20,외피index!$B$78), IF(D20=외피index!$B$79,COUNTIF($D$2:D20,외피index!$B$79), IF(D20=외피index!$B$80,COUNTIF($D$2:D20,외피index!$B$80), IF(D20=외피index!$B$82,COUNTIF($D$2:D20,외피index!$B$82), IF(D20=외피index!$B$83,COUNTIF($D$2:D20,외피index!$B$83), IF(D20=외피index!$B$84,COUNTIF($D$2:D20,외피index!$B$84), IF(D20=외피index!$B$85,COUNTIF($D$2:D20,외피index!$B$85), IF(D20=외피index!$B$86,COUNTIF($D$2:D20,외피index!$B$86), IF(D20=외피index!$B$87,COUNTIF($D$2:D20,외피index!$B$87))))))))))))))
A21: =IF(D21="","",INDEX(외피index!$C$75:$C$87,MATCH(D21,외피index!$B$75:$B$87,0),1)&"_"& IF(D21=외피index!$B$75,COUNTIF($D$2:D21,외피index!$B$75), IF(D21=외피index!$B$76,COUNTIF($D$2:D21,외피index!$B$76), IF(D21=외피index!$B$77,COUNTIF($D$2:D21,외피index!$B$77), IF(D21=외피index!$B$78,COUNTIF($D$2:D21,외피index!$B$78), IF(D21=외피index!$B$79,COUNTIF($D$2:D21,외피index!$B$79), IF(D21=외피index!$B$80,COUNTIF($D$2:D21,외피index!$B$80), IF(D21=외피index!$B$82,COUNTIF($D$2:D21,외피index!$B$82), IF(D21=외피index!$B$83,COUNTIF($D$2:D21,외피index!$B$83), IF(D21=외피index!$B$84,COUNTIF($D$2:D21,외피index!$B$84), IF(D21=외피index!$B$85,COUNTIF($D$2:D21,외피index!$B$85), IF(D21=외피index!$B$86,COUNTIF($D$2:D21,외피index!$B$86), IF(D21=외피index!$B$87,COUNTIF($D$2:D21,외피index!$B$87))))))))))))))
A22: =IF(D22="","",INDEX(외피index!$C$75:$C$87,MATCH(D22,외피index!$B$75:$B$87,0),1)&"_"& IF(D22=외피index!$B$75,COUNTIF($D$2:D22,외피index!$B$75), IF(D22=외피index!$B$76,COUNTIF($D$2:D22,외피index!$B$76), IF(D22=외피index!$B$77,COUNTIF($D$2:D22,외피index!$B$77), IF(D22=외피index!$B$78,COUNTIF($D$2:D22,외피index!$B$78), IF(D22=외피index!$B$79,COUNTIF($D$2:D22,외피index!$B$79), IF(D22=외피index!$B$80,COUNTIF($D$2:D22,외피index!$B$80), IF(D22=외피index!$B$82,COUNTIF($D$2:D22,외피index!$B$82), IF(D22=외피index!$B$83,COUNTIF($D$2:D22,외피index!$B$83), IF(D22=외피index!$B$84,COUNTIF($D$2:D22,외피index!$B$84), IF(D22=외피index!$B$85,COUNTIF($D$2:D22,외피index!$B$85), IF(D22=외피index!$B$86,COUNTIF($D$2:D22,외피index!$B$86), IF(D22=외피index!$B$87,COUNTIF($D$2:D22,외피index!$B$87))))))))))))))
A23: =IF(D23="","",INDEX(외피index!$C$75:$C$87,MATCH(D23,외피index!$B$75:$B$87,0),1)&"_"& IF(D23=외피index!$B$75,COUNTIF($D$2:D23,외피index!$B$75), IF(D23=외피index!$B$76,COUNTIF($D$2:D23,외피index!$B$76), IF(D23=외피index!$B$77,COUNTIF($D$2:D23,외피index!$B$77), IF(D23=외피index!$B$78,COUNTIF($D$2:D23,외피index!$B$78), IF(D23=외피index!$B$79,COUNTIF($D$2:D23,외피index!$B$79), IF(D23=외피index!$B$80,COUNTIF($D$2:D23,외피index!$B$80), IF(D23=외피index!$B$82,COUNTIF($D$2:D23,외피index!$B$82), IF(D23=외피index!$B$83,COUNTIF($D$2:D23,외피index!$B$83), IF(D23=외피index!$B$84,COUNTIF($D$2:D23,외피index!$B$84), IF(D23=외피index!$B$85,COUNTIF($D$2:D23,외피index!$B$85), IF(D23=외피index!$B$86,COUNTIF($D$2:D23,외피index!$B$86), IF(D23=외피index!$B$87,COUNTIF($D$2:D23,외피index!$B$87))))))))))))))
