Workbook

Sheet ZoneGeneral_3D
A1: 존번호 | B1: 층 | C1: 바닥면적
A2: =IFERROR(IF(B2="","",IF(ROW(B2)-1>99,B2&"F_Zone"&ROW(B2)-1,IF(ROW(B2)-1>9, B2&"F_Zone0"&ROW(B2)-1,B2&"F_Zone00"&ROW(B2)-1))),"") -> 1F_Zone001 | B2: 1 | C2: 42.639959
A3: =IFERROR(IF(B3="","",IF(ROW(B3)-1>99,B3&"F_Zone"&ROW(B3)-1,IF(ROW(B3)-1>9, B3&"F_Zone0"&ROW(B3)-1,B3&"F_Zone00"&ROW(B3)-1))),"") -> 1F_Zone002 | B3: 1 | C3: 24.079943
A4: =IFERROR(IF(B4="","",IF(ROW(B4)-1>99,B4&"F_Zone"&ROW(B4)-1,IF(ROW(B4)-1>9, B4&"F_Zone0"&ROW(B4)-1,B4&"F_Zone00"&ROW(B4)-1))),"") -> 1F_Zone003 | B4: 1 | C4: 10.920057
A5: =IFERROR(IF(B5="","",IF(ROW(B5)-1>99,B5&"F_Zone"&ROW(B5)-1,IF(ROW(B5)-1>9, B5&"F_Zone0"&ROW(B5)-1,B5&"F_Zone00"&ROW(B5)-1))),"") -> 1F_Zone004 | B5: 1 | C5: 3.7170383
A6: =IFERROR(IF(B6="","",IF(ROW(B6)-1>99,B6&"F_Zone"&ROW(B6)-1,IF(ROW(B6)-1>9, B6&"F_Zone0"&ROW(B6)-1,B6&"F_Zone00"&ROW(B6)-1))),"") -> 2F_Zone005 | B6: 2 | C6: 42.639959
A7: =IFERROR(IF(B7="","",IF(ROW(B7)-1>99,B7&"F_Zone"&ROW(B7)-1,IF(ROW(B7)-1>9, B7&"F_Zone0"&ROW(B7)-1,B7&"F_Zone00"&ROW(B7)-1))),"") -> 2F_Zone006 | B7: 2 | C7: 22.879955
A8: =IFERROR(IF(B8="","",IF(ROW(B8)-1>99,B8&"F_Zone"&ROW(B8)-1,IF(ROW(B8)-1>9, B8&"F_Zone0"&ROW(B8)-1,B8&"F_Zone00"&ROW(B8)-1))),"") -> 2F_Zone007 | B8: 2 | C8: 23.684919
A9: =IFERROR(IF(B9="","",IF(ROW(B9)-1>99,B9&"F_Zone"&ROW(B9)-1,IF(ROW(B9)-1>9, B9&"F_Zone0"&ROW(B9)-1,B9&"F_Zone00"&ROW(B9)-1))),"") -> 2F_Zone008 | B9: 2 | C9: 14.040055
A10: =IFERROR(IF(B10="","",IF(ROW(B10)-1>99,B10&"F_Zone"&ROW(B10)-1,IF(ROW(B10)-1>9, B10&"F_Zone0"&ROW(B10)-1,B10&"F_Zone00"&ROW(B10)-1))),"") -> 2F_Zone009 | B10: 2 | C10: 13.230021
A11: =IFERROR(IF(B11="","",IF(ROW(B11)-1>99,B11&"F_Zone"&ROW(B11)-1,IF(ROW(B11)-1>9, B11&"F_Zone0"&ROW(B11)-1,B11&"F_Zone00"&ROW(B11)-1))),"") -> 2F_Zone010 | B11: 2 | C11: 18.200043
A12: =IFERROR(IF(B12="","",IF(ROW(B12)-1>99,B12&"F_Zone"&ROW(B12)-1,IF(ROW(B12)-1>9, B12&"F_Zone0"&ROW(B12)-1,B12&"F_Zone00"&ROW(B12)-1))),"") -> 2F_Zone011 | B12: 2 | C12: 10.58506
A13: =IFERROR(IF(B13="","",IF(ROW(B13)-1>99,B13&"F_Zone"&ROW(B13)-1,IF(ROW(B13)-1>9, B13&"F_Zone0"&ROW(B13)-1,B13&"F_Zone00"&ROW(B13)-1))),"") -> 2F_Zone012 | B13: 2 | C13: 4.7999878
... A21: =IFERROR(IF(B21="","",IF(ROW(B21)-1>99,B21&"F_Zone"&ROW(B21)-1,IF(ROW(B21)-1>9, B21&"F_Zone0"&ROW(B21)-1,B21&"F_Zone00"&ROW(B21)-1))),"") -> 4F_Zone020 | B21: 4 | C21: 16.799957

Sheet ZoneEnvelope_3D
A1: 번호 | B1: 층 | C1: 존 | D1: 외피유형 | E1: 커튼월부위 | F1: 면적 | G1: 인접존 | H1: 방위 | I1: 기울기 | J1: 우측면돌출길이 | K1: 좌측면돌출길이 | L1: 상부돌출길이 | M1: 주변요소음영길이 | N1: 벽체길이 | O1: 창호너비 | P1: 창호높이
A2: =IFERROR(IF(D2="","",C2&"_"& IF($D2=외피index!$B$3, 외피index!$C$3&"_"&COUNTIFS(D2:$D$2,외피index!$B$3,C2:$C$2,C2), IF($D2=외피index!$B$4, 외피index!$C$4&"_"&COUNTIFS(D2:$D$2,외피index!$B$4,C2:$C$2,C2), IF($D2=외피index!$B$5, 외피index!$C$5&"_"&COUNTIFS(D2:$D$2,외피index!$B$5,C2:$C$2,C2), IF($D2=외피index!$B$6, 외피index!$C$6&"_"&COUNTIFS(D2:$D$2,외피index!$B$6,C2:$C$2,C2), IF($D2=외피index!$B$7, 외피index!$C$7&"_"&COUNTIFS(D2:$D$2,외피index!$B$7,C2:$C$2,C2), IF($D2=외피index!$B$8, 외피index!$C$8&"_"&COUNTIFS(D2:$D$2,외피index!$B$8,C2:$C$2,C2), IF($D2=외피index!$B$9, 외피index!$C$9&"_"&COUNTIFS(D2:$D$2,외피index!$B$9,C2:$C$2,C2), IF($D2=외피index!$B$10, 외피index!$C$10&"_"&COUNTIFS(D2:$D$2,외피index!$B$10,C2:$C$2,C2), 0))))))))),"") -> 2F_Zone006_SL_1 | B2: 2F | C2: 2F_Zone006 | D2: 층간바닥 | F2: 28.080031 | G2: 3F_Zone014 | H2: 수평 | I2: 180
A3: =IFERROR(IF(D3="","",C3&"_"& IF($D3=외피index!$B$3, 외피index!$C$3&"_"&COUNTIFS(D$2:$D3,외피index!$B$3,C$2:$C3,C3), IF($D3=외피index!$B$4, 외피index!$C$4&"_"&COUNTIFS(D$2:$D3,외피index!$B$4,C$2:$C3,C3), IF($D3=외피index!$B$5, 외피index!$C$5&"_"&COUNTIFS(D$2:$D3,외피index!$B$5,C$2:$C3,C3), IF($D3=외피index!$B$6, 외피index!$C$6&"_"&COUNTIFS(D$2:$D3,외피index!$B$6,C$2:$C3,C3), IF($D3=외피index!$B$7, 외피index!$C$7&"_"&COUNTIFS(D$2:$D3,외피index!$B$7,C$2:$C3,C3), IF($D3=외피index!$B$8, 외피index!$C$8&"_"&COUNTIFS(D$2:$D3,외피index!$B$8,C$2:$C3,C3), IF($D3=외피index!$B$9, 외피index!$C$9&"_"&COUNTIFS(D$2:$D3,외피index!$B$9,C$2:$C3,C3), IF($D3=외피index!$B$10, 외피index!$C$10&"_"&COUNTIFS(D$2:$D3,외피index!$B$10,C$2:$C3,C3), 0))))))))),"") -> 2F_Zone007_SL_1 | B3: 2F | C3: 2F_Zone007 | D3: 층간바닥 | F3: 22.879955 | G3: 3F_Zone015 | H3: 수평 | I3: 180
A4: =IFERROR(IF(D4="","",C4&"_"& IF($D4=외피index!$B$3, 외피index!$C$3&"_"&COUNTIFS(D$2:$D4,외피index!$B$3,C$2:$C4,C4), IF($D4=외피index!$B$4, 외피index!$C$4&"_"&COUNTIFS(D$2:$D4,외피index!$B$4,C$2:$C4,C4), IF($D4=외피index!$B$5, 외피index!$C$5&"_"&COUNTIFS(D$2:$D4,외피index!$B$5,C$2:$C4,C4), IF($D4=외피index!$B$6, 외피index!$C$6&"_"&COUNTIFS(D$2:$D4,외피index!$B$6,C$2:$C4,C4), IF($D4=외피index!$B$7, 외피index!$C$7&"_"&COUNTIFS(D$2:$D4,외피index!$B$7,C$2:$C4,C4), IF($D4=외피index!$B$8, 외피index!$C$8&"_"&COUNTIFS(D$2:$D4,외피index!$B$8,C$2:$C4,C4), IF($D4=외피index!$B$9, 외피index!$C$9&"_"&COUNTIFS(D$2:$D4,외피index!$B$9,C$2:$C4,C4), IF($D4=외피index!$B$10, 외피index!$C$10&"_"&COUNTIFS(D$2:$D4,외피index!$B$10,C$2:$C4,C4), 0))))))))),"") -> 2F_Zone011_RF_1 | B4: 2F | C4: 2F_Zone011 | D4: 지붕 | F4: 18.200043 | H4: 수평 | I4: 0
A5: =IFERROR(IF(D5="","",C5&"_"& IF($D5=외피index!$B$3, 외피index!$C$3&"_"&COUNTIFS(D$2:$D5,외피index!$B$3,C$2:$C5,C5), IF($D5=외피index!$B$4, 외피index!$C$4&"_"&COUNTIFS(D$2:$D5,외피index!$B$4,C$2:$C5,C5), IF($D5=외피index!$B$5, 외피index!$C$5&"_"&COUNTIFS(D$2:$D5,외피index!$B$5,C$2:$C5,C5), IF($D5=외피index!$B$6, 외피index!$C$6&"_"&COUNTIFS(D$2:$D5,외피index!$B$6,C$2:$C5,C5), IF($D5=외피index!$B$7, 외피index!$C$7&"_"&COUNTIFS(D$2:$D5,외피index!$B$7,C$2:$C5,C5), IF($D5=외피index!$B$8, 외피index!$C$8&"_"&COUNTIFS(D$2:$D5,외피index!$B$8,C$2:$C5,C5), IF($D5=외피index!$B$9, 외피index!$C$9&"_"&COUNTIFS(D$2:$D5,외피index!$B$9,C$2:$C5,C5), IF($D5=외피index!$B$10, 외피index!$C$10&"_"&COUNTIFS(D$2:$D5,외피index!$B$10,C$2:$C5,C5), 0))))))))),"") -> 2F_Zone008_SL_1 | B5: 2F | C5: 2F_Zone008 | D5: 층간바닥 | F5: 15.449966 | G5: 3F_Zone016 | H5: 수평 | I5: 0
A6: =IFERROR(IF(D6="","",C6&"_"& IF($D6=외피index!$B$3, 외피index!$C$3&"_"&COUNTIFS(D$2:$D6,외피index!$B$3,C$2:$C6,C6), IF($D6=외피index!$B$4, 외피index!$C$4&"_"&COUNTIFS(D$2:$D6,외피index!$B$4,C$2:$C6,C6), IF($D6=외피index!$B$5, 외피index!$C$5&"_"&COUNTIFS(D$2:$D6,외피index!$B$5,C$2:$C6,C6), IF($D6=외피index!$B$6, 외피index!$C$6&"_"&COUNTIFS(D$2:$D6,외피index!$B$6,C$2:$C6,C6), IF($D6=외피index!$B$7, 외피index!$C$7&"_"&COUNTIFS(D$2:$D6,외피index!$B$7,C$2:$C6,C6), IF($D6=외피index!$B$8, 외피index!$C$8&"_"&COUNTIFS(D$2:$D6,외피index!$B$8,C$2:$C6,C6), IF($D6=외피index!$B$9, 외피index!$C$9&"_"&COUNTIFS(D$2:$D6,외피index!$B$9,C$2:$C6,C6), IF($D6=외피index!$B$10, 외피index!$C$10&"_"&COUNTIFS(D$2:$D6,외피index!$B$10,C$2:$C6,C6), 0))))))))),"") -> 2F_Zone009_SL_1 | B6: 2F | C6: 2F_Zone009 | D6: 층간바닥 | F6: 14.040055 | G6: 3F_Zone015 | H6: 수평 | I6: 180
A7: =IFERROR(IF(D7="","",C7&"_"& IF($D7=외피index!$B$3, 외피index!$C$3&"_"&COUNTIFS(D$2:$D7,외피index!$B$3,C$2:$C7,C7), IF($D7=외피index!$B$4, 외피index!$C$4&"_"&COUNTIFS(D$2:$D7,외피index!$B$4,C$2:$C7,C7), IF($D7=외피index!$B$5, 외피index!$C$5&"_"&COUNTIFS(D$2:$D7,외피index!$B$5,C$2:$C7,C7), IF($D7=외피index!$B$6, 외피index!$C$6&"_"&COUNTIFS(D$2:$D7,외피index!$B$6,C$2:$C7,C7), IF($D7=외피index!$B$7, 외피index!$C$7&"_"&COUNTIFS(D$2:$D7,외피index!$B$7,C$2:$C7,C7), IF($D7=외피index!$B$8, 외피index!$C$8&"_"&COUNTIFS(D$2:$D7,외피index!$B$8,C$2:$C7,C7), IF($D7=외피index!$B$9, 외피index!$C$9&"_"&COUNTIFS(D$2:$D7,외피index!$B$9,C$2:$C7,C7), IF($D7=외피index!$B$10, 외피index!$C$10&"_"&COUNTIFS(D$2:$D7,외피index!$B$10,C$2:$C7,C7), 0))))))))),"") -> 2F_Zone010_RF_1 | B7: 2F | C7: 2F_Zone010 | D7: 지붕 | F7: 10.920018 | H7: 수평 | I7: 0
A8: =IFERROR(IF(D8="","",C8&"_"& IF($D8=외피index!$B$3, 외피index!$C$3&"_"&COUNTIFS(D$2:$D8,외피index!$B$3,C$2:$C8,C8), IF($D8=외피index!$B$4, 외피index!$C$4&"_"&COUNTIFS(D$2:$D8,외피index!$B$4,C$2:$C8,C8), IF($D8=외피index!$B$5, 외피index!$C$5&"_"&COUNTIFS(D$2:$D8,외피index!$B$5,C$2:$C8,C8), IF($D8=외피index!$B$6, 외피index!$C$6&"_"&COUNTIFS(D$2:$D8,외피index!$B$6,C$2:$C8,C8), IF($D8=외피index!$B$7, 외피index!$C$7&"_"&COUNTIFS(D$2:$D8,외피index!$B$7,C$2:$C8,C8), IF($D8=외피index!$B$8, 외피index!$C$8&"_"&COUNTIFS(D$2:$D8,외피index!$B$8,C$2:$C8,C8), IF($D8=외피index!$B$9, 외피index!$C$9&"_"&COUNTIFS(D$2:$D8,외피index!$B$9,C$2:$C8,C8), IF($D8=외피index!$B$10, 외피index!$C$10&"_"&COUNTIFS(D$2:$D8,외피index!$B$10,C$2:$C8,C8), 0))))))))),"") -> 2F_Zone006_SL_2 | B8: 2F | C8: 2F_Zone006 | D8: 층간바닥 | F8: 8.6799365 | G8: 3F_Zone017 | H8: 수평 | I8: 180
A9: =IFERROR(IF(D9="","",C9&"_"& IF($D9=외피index!$B$3, 외피index!$C$3&"_"&COUNTIFS(D$2:$D9,외피index!$B$3,C$2:$C9,C9), IF($D9=외피index!$B$4, 외피index!$C$4&"_"&COUNTIFS(D$2:$D9,외피index!$B$4,C$2:$C9,C9), IF($D9=외피index!$B$5, 외피index!$C$5&"_"&COUNTIFS(D$2:$D9,외피index!$B$5,C$2:$C9,C9), IF($D9=외피index!$B$6, 외피index!$C$6&"_"&COUNTIFS(D$2:$D9,외피index!$B$6,C$2:$C9,C9), IF($D9=외피index!$B$7, 외피index!$C$7&"_"&COUNTIFS(D$2:$D9,외피index!$B$7,C$2:$C9,C9), IF($D9=외피index!$B$8, 외피index!$C$8&"_"&COUNTIFS(D$2:$D9,외피index!$B$8,C$2:$C9,C9), IF($D9=외피index!$B$9, 외피index!$C$9&"_"&COUNTIFS(D$2:$D9,외피index!$B$9,C$2:$C9,C9), IF($D9=외피index!$B$10, 외피index!$C$10&"_"&COUNTIFS(D$2:$D9,외피index!$B$10,C$2:$C9,C9), 0))))))))),"") -> 2F_Zone012_RF_1 | B9: 2F | C9: 2F_Zone012 | D9: 지붕 | F9: 7.5400415 | H9: 수평 | I9: 0
A10: =IFERROR(IF(D10="","",C10&"_"& IF($D10=외피index!$B$3, 외피index!$C$3&"_"&COUNTIFS(D$2:$D10,외피index!$B$3,C$2:$C10,C10), IF($D10=외피index!$B$4, 외피index!$C$4&"_"&COUNTIFS(D$2:$D10,외피index!$B$4,C$2:$C10,C10), IF($D10=외피index!$B$5, 외피index!$C$5&"_"&COUNTIFS(D$2:$D10,외피index!$B$5,C$2:$C10,C10), IF($D10=외피index!$B$6, 외피index!$C$6&"_"&COUNTIFS(D$2:$D10,외피index!$B$6,C$2:$C10,C10), IF($D10=외피index!$B$7, 외피index!$C$7&"_"&COUNTIFS(D$2:$D10,외피index!$B$7,C$2:$C10,C10), IF($D10=외피index!$B$8, 외피index!$C$8&"_"&COUNTIFS(D$2:$D10,외피index!$B$8,C$2:$C10,C10), IF($D10=외피index!$B$9, 외피index!$C$9&"_"&COUNTIFS(D$2:$D10,외피index!$B$9,C$2:$C10,C10), IF($D10=외피index!$B$10, 외피index!$C$10&"_"&COUNTIFS(D$2:$D10,외피index!$B$10,C$2:$C10,C10), 0))))))))),"") -> 2F_Zone006_SL_3 | B10: 2F | C10: 2F_Zone006 | D10: 층간바닥 | F10: 5.8799915 | G10: 3F_Zone016 | H10: 수평 | I10: 0
A11: =IFERROR(IF(D11="","",C11&"_"& IF($D11=외피index!$B$3, 외피index!$C$3&"_"&COUNTIFS(D$2:$D11,외피index!$B$3,C$2:$C11,C11), IF($D11=외피index!$B$4, 외피index!$C$4&"_"&COUNTIFS(D$2:$D11,외피index!$B$4,C$2:$C11,C11), IF($D11=외피index!$B$5, 외피index!$C$5&"_"&COUNTIFS(D$2:$D11,외피index!$B$5,C$2:$C11,C11), IF($D11=외피index!$B$6, 외피index!$C$6&"_"&COUNTIFS(D$2:$D11,외피index!$B$6,C$2:$C11,C11), IF($D11=외피index!$B$7, 외피index!$C$7&"_"&COUNTIFS(D$2:$D11,외피index!$B$7,C$2:$C11,C11), IF($D11=외피index!$B$8, 외피index!$C$8&"_"&COUNTIFS(D$2:$D11,외피index!$B$8,C$2:$C11,C11), IF($D11=외피index!$B$9, 외피index!$C$9&"_"&COUNTIFS(D$2:$D11,외피index!$B$9,C$2:$C11,C11), IF($D11=외피index!$B$10, 외피index!$C$10&"_"&COUNTIFS(D$2:$D11,외피index!$B$10,C$2:$C11,C11), 0))))))))),"") -> 2F_Zone008_SL_2 | B11: 2F | C11: 2F_Zone008 | D11: 층간바닥 | F11: 5.5822345 | G11: 3F_Zone019 | H11: 수평 | I11: 0
A12: =IFERROR(IF(D12="","",C12&"_"& IF($D12=외피index!$B$3, 외피index!$C$3&"_"&COUNTIFS(D$2:$D12,외피index!$B$3,C$2:$C12,C12), IF($D12=외피index!$B$4, 외피index!$C$4&"_"&COUNTIFS(D$2:$D12,외피index!$B$4,C$2:$C12,C12), IF($D12=외피index!$B$5, 외피index!$C$5&"_"&COUNTIFS(D$2:$D12,외피index!$B$5,C$2:$C12,C12), IF($D12=외피index!$B$6, 외피index!$C$6&"_"&COUNTIFS(D$2:$D12,외피index!$B$6,C$2:$C12,C12), IF($D12=외피index!$B$7, 외피index!$C$7&"_"&COUNTIFS(D$2:$D12,외피index!$B$7,C$2:$C12,C12), IF($D12=외피index!$B$8, 외피index!$C$8&"_"&COUNTIFS(D$2:$D12,외피index!$B$8,C$2:$C12,C12), IF($D12=외피index!$B$9, 외피index!$C$9&"_"&COUNTIFS(D$2:$D12,외피index!$B$9,C$2:$C12,C12), IF($D12=외피index!$B$10, 외피index!$C$10&"_"&COUNTIFS(D$2:$D12,외피index!$B$10,C$2:$C12,C12), 0))))))))),"") -> 2F_Zone013_SL_1 | B12: 2F | C12: 2F_Zone013 | D12: 층간바닥 | F12: 4.7999878 | G12: 3F_Zone020 | H12: 수평 | I12: 180
A13: =IFERROR(IF(D13="","",C13&"_"& IF($D13=외피index!$B$3, 외피index!$C$3&"_"&COUNTIFS(D$2:$D13,외피index!$B$3,C$2:$C13,C13), IF($D13=외피index!$B$4, 외피index!$C$4&"_"&COUNTIFS(D$2:$D13,외피index!$B$4,C$2:$C13,C13), IF($D13=외피index!$B$5, 외피index!$C$5&"_"&COUNTIFS(D$2:$D13,외피index!$B$5,C$2:$C13,C13), IF($D13=외피index!$B$6, 외피index!$C$6&"_"&COUNTIFS(D$2:$D13,외피index!$B$6,C$2:$C13,C13), IF($D13=외피index!$B$7, 외피index!$C$7&"_"&COUNTIFS(D$2:$D13,외피index!$B$7,C$2:$C13,C13), IF($D13=외피index!$B$8, 외피index!$C$8&"_"&COUNTIFS(D$2:$D13,외피index!$B$8,C$2:$C13,C13), IF($D13=외피index!$B$9, 외피index!$C$9&"_"&COUNTIFS(D$2:$D13,외피index!$B$9,C$2:$C13,C13), IF($D13=외피index!$B$10, 외피index!$C$10&"_"&COUNTIFS(D$2:$D13,외피index!$B$10,C$2:$C13,C13), 0))))))))),"") -> 2F_Zone012_SL_1 | B13: 2F | C13: 2F_Zone012 | D13: 층간바닥 | F13: 1.8900087 | G13: 3F_Zone018 | H13: 수평 | I13: 0
A14: =IFERROR(IF(D14="","",C14&"_"& IF($D14=외피index!$B$3, 외피index!$C$3&"_"&COUNTIFS(D$2:$D14,외피index!$B$3,C$2:$C14,C14), IF($D14=외피index!$B$4, 외피index!$C$4&"_"&COUNTIFS(D$2:$D14,외피index!$B$4,C$2:$C14,C14), IF($D14=외피index!$B$5, 외피index!$C$5&"_"&COUNTIFS(D$2:$D14,외피index!$B$5,C$2:$C14,C14), IF($D14=외피index!$B$6, 외피index!$C$6&"_"&COUNTIFS(D$2:$D14,외피index!$B$6,C$2:$C14,C14), IF($D14=외피index!$B$7, 외피index!$C$7&"_"&COUNTIFS(D$2:$D14,외피index!$B$7,C$2:$C14,C14), IF($D14=외피index!$B$8, 외피index!$C$8&"_"&COUNTIFS(D$2:$D14,외피index!$B$8,C$2:$C14,C14), IF($D14=외피index!$B$9, 외피index!$C$9&"_"&COUNTIFS(D$2:$D14,외피index!$B$9,C$2:$C14,C14), IF($D14=외피index!$B$10, 외피index!$C$10&"_"&COUNTIFS(D$2:$D14,외피index!$B$10,C$2:$C14,C14), 0))))))))),"") -> 2F_Zone010_SL_1 | B14: 2F | C14: 2F_Zone010 | D14: 층간바닥 | F14: 1.7167492 | G14: 3F_Zone019 | H14: 수평 | I14: 0
A15: =IFERROR(IF(D15="","",C15&"_"& IF($D15=외피index!$B$3, 외피index!$C$3&"_"&COUNTIFS(D$2:$D15,외피index!$B$3,C$2:$C15,C15), IF($D15=외피index!$B$4, 외피index!$C$4&"_"&COUNTIFS(D$2:$D15,외피index!$B$4,C$2:$C15,C15), IF($D15=외피index!$B$5, 외피index!$C$5&"_"&COUNTIFS(D$2:$D15,외피index!$B$5,C$2:$C15,C15), IF($D15=외피index!$B$6, 외피index!$C$6&"_"&COUNTIFS(D$2:$D15,외피index!$B$6,C$2:$C15,C15), IF($D15=외피index!$B$7, 외피index!$C$7&"_"&COUNTIFS(D$2:$D15,외피index!$B$7,C$2:$C15,C15), IF($D15=외피index!$B$8, 외피index!$C$8&"_"&COUNTIFS(D$2:$D15,외피index!$B$8,C$2:$C15,C15), IF($D15=외피index!$B$9, 외피index!$C$9&"_"&COUNTIFS(D$2:$D15,외피index!$B$9,C$2:$C15,C15), IF($D15=외피index!$B$10, 외피index!$C$10&"_"&COUNTIFS(D$2:$D15,외피index!$B$10,C$2:$C15,C15), 0))))))))),"") -> 2F_Zone012_SL_2 | B15: 2F | C15: 2F_Zone012 | D15: 층간바닥 | F15: 1.1550098 | G15: 3F_Zone019 | H15: 수평 | I15: 0
A16: =IFERROR(IF(D16="","",C16&"_"& IF($D16=외피index!$B$3, 외피index!$C$3&"_"&COUNTIFS(D$2:$D16,외피index!$B$3,C$2:$C16,C16), IF($D16=외피index!$B$4, 외피index!$C$4&"_"&COUNTIFS(D$2:$D16,외피index!$B$4,C$2:$C16,C16), IF($D16=외피index!$B$5, 외피index!$C$5&"_"&COUNTIFS(D$2:$D16,외피index!$B$5,C$2:$C16,C16), IF($D16=외피index!$B$6, 외피index!$C$6&"_"&COUNTIFS(D$2:$D16,외피index!$B$6,C$2:$C16,C16), IF($D16=외피index!$B$7, 외피index!$C$7&"_"&COUNTIFS(D$2:$D16,외피index!$B$7,C$2:$C16,C16), IF($D16=외피index!$B$8, 외피index!$C$8&"_"&COUNTIFS(D$2:$D16,외피index!$B$8,C$2:$C16,C16), IF($D16=외피index!$B$9, 외피index!$C$9&"_"&COUNTIFS(D$2:$D16,외피index!$B$9,C$2:$C16,C16), IF($D16=외피index!$B$10, 외피index!$C$10&"_"&COUNTIFS(D$2:$D16,외피index!$B$10,C$2:$C16,C16), 0))))))))),"") -> 2F_Zone008_SL_3 | B16: 2F | C16: 2F_Zone008 | D16: 층간바닥 | F16: 0.76274812 | G16: 3F_Zone020 | H16: 수평 | I16: 0
A17: =IFERROR(IF(D17="","",C17&"_"& IF($D17=외피index!$B$3, 외피index!$C$3&"_"&COUNTIFS(D$2:$D17,외피index!$B$3,C$2:$C17,C17), IF($D17=외피index!$B$4, 외피index!$C$4&"_"&COUNTIFS(D$2:$D17,외피index!$B$4,C$2:$C17,C17), IF($D17=외피index!$B$5, 외피index!$C$5&"_"&COUNTIFS(D$2:$D17,외피index!$B$5,C$2:$C17,C17), IF($D17=외피index!$B$6, 외피index!$C$6&"_"&COUNTIFS(D$2:$D17,외피index!$B$6,C$2:$C17,C17), IF($D17=외피index!$B$7, 외피index!$C$7&"_"&COUNTIFS(D$2:$D17,외피index!$B$7,C$2:$C17,C17), IF($D17=외피index!$B$8, 외피index!$C$8&"_"&COUNTIFS(D$2:$D17,외피index!$B$8,C$2:$C17,C17), IF($D17=외피index!$B$9, 외피index!$C$9&"_"&COUNTIFS(D$2:$D17,외피index!$B$9,C$2:$C17,C17), IF($D17=외피index!$B$10, 외피index!$C$10&"_"&COUNTIFS(D$2:$D17,외피index!$B$10,C$2:$C17,C17), 0))))))))),"") -> 2F_Zone010_SL_2 | B17: 2F | C17: 2F_Zone010 | D17: 층간바닥 | F17: 0.59325429 | G17: 3F_Zone020 | H17: 수평 | I17: 0
A18: =IFERROR(IF(D18="","",C18&"_"& IF($D18=외피index!$B$3, 외피index!$C$3&"_"&COUNTIFS(D$2:$D18,외피index!$B$3,C$2:$C18,C18), IF($D18=외피index!$B$4, 외피index!$C$4&"_"&COUNTIFS(D$2:$D18,외피index!$B$4,C$2:$C18,C18), IF($D18=외피index!$B$5, 외피index!$C$5&"_"&COUNTIFS(D$2:$D18,외피index!$B$5,C$2:$C18,C18), IF($D18=외피index!$B$6, 외피index!$C$6&"_"&COUNTIFS(D$2:$D18,외피index!$B$6,C$2:$C18,C18), IF($D18=외피index!$B$7, 외피index!$C$7&"_"&COUNTIFS(D$2:$D18,외피index!$B$7,C$2:$C18,C18), IF($D18=외피index!$B$8, 외피index!$C$8&"_"&COUNTIFS(D$2:$D18,외피index!$B$8,C$2:$C18,C18), IF($D18=외피index!$B$9, 외피index!$C$9&"_"&COUNTIFS(D$2:$D18,외피index!$B$9,C$2:$C18,C18), IF($D18=외피index!$B$10, 외피index!$C$10&"_"&COUNTIFS(D$2:$D18,외피index!$B$10,C$2:$C18,C18), 0))))))))),"") -> 3F_Zone015_RF_1 | B18: 3F | C18: 3F_Zone015 | D18: 지붕 | F18: 36.92001 | H18: 수평 | I18: 0
A19: =IFERROR(IF(D19="","",C19&"_"& IF($D19=외피index!$B$3, 외피index!$C$3&"_"&COUNTIFS(D$2:$D19,외피index!$B$3,C$2:$C19,C19), IF($D19=외피index!$B$4, 외피index!$C$4&"_"&COUNTIFS(D$2:$D19,외피index!$B$4,C$2:$C19,C19), IF($D19=외피index!$B$5, 외피index!$C$5&"_"&COUNTIFS(D$2:$D19,외피index!$B$5,C$2:$C19,C19), IF($D19=외피index!$B$6, 외피index!$C$6&"_"&COUNTIFS(D$2:$D19,외피index!$B$6,C$2:$C19,C19), IF($D19=외피index!$B$7, 외피index!$C$7&"_"&COUNTIFS(D$2:$D19,외피index!$B$7,C$2:$C19,C19), IF($D19=외피index!$B$8, 외피index!$C$8&"_"&COUNTIFS(D$2:$D19,외피index!$B$8,C$2:$C19,C19), IF($D19=외피index!$B$9, 외피index!$C$9&"_"&COUNTIFS(D$2:$D19,외피index!$B$9,C$2:$C19,C19), IF($D19=외피index!$B$10, 외피index!$C$10&"_"&COUNTIFS(D$2:$D19,외피index!$B$10,C$2:$C19,C19), 0))))))))),"") -> 3F_Zone014_RF_1 | B19: 3F | C19: 3F_Zone014 | D19: 지붕 | F19: 28.080031 | H19: 수평 | I19: 0
A20: =IFERROR(IF(D20="","",C20&"_"& IF($D20=외피index!$B$3, 외피index!$C$3&"_"&COUNTIFS(D$2:$D20,외피index!$B$3,C$2:$C20,C20), IF($D20=외피index!$B$4, 외피index!$C$4&"_"&COUNTIFS(D$2:$D20,외피index!$B$4,C$2:$C20,C20), IF($D20=외피index!$B$5, 외피index!$C$5&"_"&COUNTIFS(D$2:$D20,외피index!$B$5,C$2:$C20,C20), IF($D20=외피index!$B$6, 외피index!$C$6&"_"&COUNTIFS(D$2:$D20,외피index!$B$6,C$2:$C20,C20), IF($D20=외피index!$B$7, 외피index!$C$7&"_"&COUNTIFS(D$2:$D20,외피index!$B$7,C$2:$C20,C20), IF($D20=외피index!$B$8, 외피index!$C$8&"_"&COUNTIFS(D$2:$D20,외피index!$B$8,C$2:$C20,C20), IF($D20=외피index!$B$9, 외피index!$C$9&"_"&COUNTIFS(D$2:$D20,외피index!$B$9,C$2:$C20,C20), IF($D20=외피index!$B$10, 외피index!$C$10&"_"&COUNTIFS(D$2:$D20,외피index!$B$10,C$2:$C20,C20), 0))))))))),"") -> 3F_Zone016_SL_1 | B20: 3F | C20: 3F_Zone016 | D20: 층간바닥 | F20: 15.449966 | G20: 4F_Zone021 | H20: 수평 | I20: 180
A21: =IFERROR(IF(D21="","",C21&"_"& IF($D21=외피index!$B$3, 외피index!$C$3&"_"&COUNTIFS(D$2:$D21,외피index!$B$3,C$2:$C21,C21), IF($D21=외피index!$B$4, 외피index!$C$4&"_"&COUNTIFS(D$2:$D21,외피index!$B$4,C$2:$C21,C21), IF($D21=외피index!$B$5, 외피index!$C$5&"_"&COUNTIFS(D$2:$D21,외피index!$B$5,C$2:$C21,C21), IF($D21=외피index!$B$6, 외피index!$C$6&"_"&COUNTIFS(D$2:$D21,외피index!$B$6,C$2:$C21,C21), IF($D21=외피index!$B$7, 외피index!$C$7&"_"&COUNTIFS(D$2:$D21,외피index!$B$7,C$2:$C21,C21), IF($D21=외피index!$B$8, 외피index!$C$8&"_"&COUNTIFS(D$2:$D21,외피index!$B$8,C$2:$C21,C21), IF($D21=외피index!$B$9, 외피index!$C$9&"_"&COUNTIFS(D$2:$D21,외피index!$B$9,C$2:$C21,C21), IF($D21=외피index!$B$10, 외피index!$C$10&"_"&COUNTIFS(D$2:$D21,외피index!$B$10,C$2:$C21,C21), 0))))))))),"") -> 3F_Zone017_RF_1 | B21: 3F | C21: 3F_Zone017 | D21: 지붕 | F21: 8.6799365 | H21: 수평 | I21: 0
A22: =IFERROR(IF(D22="","",C22&"_"& IF($D22=외피index!$B$3, 외피index!$C$3&"_"&COUNTIFS(D$2:$D22,외피index!$B$3,C$2:$C22,C22), IF($D22=외피index!$B$4, 외피index!$C$4&"_"&COUNTIFS(D$2:$D22,외피index!$B$4,C$2:$C22,C22), IF($D22=외피index!$B$5, 외피index!$C$5&"_"&COUNTIFS(D$2:$D22,외피index!$B$5,C$2:$C22,C22), IF($D22=외피index!$B$6, 외피index!$C$6&"_"&COUNTIFS(D$2:$D22,외피index!$B$6,C$2:$C22,C22), IF($D22=외피index!$B$7, 외피index!$C$7&"_"&COUNTIFS(D$2:$D22,외피index!$B$7,C$2:$C22,C22), IF($D22=외피index!$B$8, 외피index!$C$8&"_"&COUNTIFS(D$2:$D22,외피index!$B$8,C$2:$C22,C22), IF($D22=외피index!$B$9, 외피index!$C$9&"_"&COUNTIFS(D$2:$D22,외피index!$B$9,C$2:$C22,C22), IF($D22=외피index!$B$10, 외피index!$C$10&"_"&COUNTIFS(D$2:$D22,외피index!$B$10,C$2:$C22,C22), 0))))))))),"") -> 3F_Zone019_RF_1 | B22: 3F | C22: 3F_Zone019 | D22: 지붕 | F22: 8.4539935 | H22: 수평 | I22: 0
A23: =IFERROR(IF(D23="","",C23&"_"& IF($D23=외피index!$B$3, 외피index!$C$3&"_"&COUNTIFS(D$2:$D23,외피index!$B$3,C$2:$C23,C23), IF($D23=외피index!$B$4, 외피index!$C$4&"_"&COUNTIFS(D$2:$D23,외피index!$B$4,C$2:$C23,C23), IF($D23=외피index!$B$5, 외피index!$C$5&"_"&COUNTIFS(D$2:$D23,외피index!$B$5,C$2:$C23,C23), IF($D23=외피index!$B$6, 외피index!$C$6&"_"&COUNTIFS(D$2:$D23,외피index!$B$6,C$2:$C23,C23), IF($D23=외피index!$B$7, 외피index!$C$7&"_"&COUNTIFS(D$2:$D23,외피index!$B$7,C$2:$C23,C23), IF($D23=외피index!$B$8, 외피index!$C$8&"_"&COUNTIFS(D$2:$D23,외피index!$B$8,C$2:$C23,C23), IF($D23=외피index!$B$9, 외피index!$C$9&"_"&COUNTIFS(D$2:$D23,외피index!$B$9,C$2:$C23,C23), IF($D23=외피index!$B$10, 외피index!$C$10&"_"&COUNTIFS(D$2:$D23,외피index!$B$10,C$2:$C23,C23), 0))))))))),"") -> 3F_Zone020_RF_1 | B23: 3F | C23: 3F_Zone020 | D23: 지붕 | F23: 6.1559902 | H23: 수평 | I23: 0
A24: =IFERROR(IF(D24="","",C24&"_"& IF($D24=외피index!$B$3, 외피index!$C$3&"_"&COUNTIFS(D$2:$D24,외피index!$B$3,C$2:$C24,C24), IF($D24=외피index!$B$4, 외피index!$C$4&"_"&COUNTIFS(D$2:$D24,외피index!$B$4,C$2:$C24,C24), IF($D24=외피index!$B$5, 외피index!$C$5&"_"&COUNTIFS(D$2:$D24,외피index!$B$5,C$2:$C24,C24), IF($D24=외피index!$B$6, 외피index!$C$6&"_"&COUNTIFS(D$2:$D24,외피index!$B$6,C$2:$C24,C24), IF($D24=외피index!$B$7, 외피index!$C$7&"_"&COUNTIFS(D$2:$D24,외피index!$B$7,C$2:$C24,C24), IF($D24=외피index!$B$8, 외피index!$C$8&"_"&COUNTIFS(D$2:$D24,외피index!$B$8,C$2:$C24,C24), IF($D24=외피index!$B$9, 외피index!$C$9&"_"&COUNTIFS(D$2:$D24,외피index!$B$9,C$2:$C24,C24), IF($D24=외피index!$B$10, 외피index!$C$10&"_"&COUNTIFS(D$2:$D24,외피index!$B$10,C$2:$C24,C24), 0))))))))),"") -> 3F_Zone016_RF_1 | B24: 3F | C24: 3F_Zone016 | D24: 지붕 | F24: 5.8799915 | H24: 수평 | I24: 0
A25: =IFERROR(IF(D25="","",C25&"_"& IF($D25=외피index!$B$3, 외피index!$C$3&"_"&COUNTIFS(D$2:$D25,외피index!$B$3,C$2:$C25,C25), IF($D25=외피index!$B$4, 외피index!$C$4&"_"&COUNTIFS(D$2:$D25,외피index!$B$4,C$2:$C25,C25), IF($D25=외피index!$B$5, 외피index!$C$5&"_"&COUNTIFS(D$2:$D25,외피index!$B$5,C$2:$C25,C25), IF($D25=외피index!$B$6, 외피index!$C$6&"_"&COUNTIFS(D$2:$D25,외피index!$B$6,C$2:$C25,C25), IF($D25=외피index!$B$7, 외피index!$C$7&"_"&COUNTIFS(D$2:$D25,외피index!$B$7,C$2:$C25,C25), IF($D25=외피index!$B$8, 외피index!$C$8&"_"&COUNTIFS(D$2:$D25,외피index!$B$8,C$2:$C25,C25), IF($D25=외피index!$B$9, 외피index!$C$9&"_"&COUNTIFS(D$2:$D25,외피index!$B$9,C$2:$C25,C25), IF($D25=외피index!$B$10, 외피index!$C$10&"_"&COUNTIFS(D$2:$D25,외피index!$B$10,C$2:$C25,C25), 0))))))))),"") -> 3F_Zone018_RF_1 | B25: 3F | C25: 3F_Zone018 | D25: 지붕 | F25: 2.4299876 | H25: 수평 | I25: 0
A26: =IFERROR(IF(D26="","",C26&"_"& IF($D26=외피index!$B$3, 외피index!$C$3&"_"&COUNTIFS(D$2:$D26,외피index!$B$3,C$2:$C26,C26), IF($D26=외피index!$B$4, 외피index!$C$4&"_"&COUNTIFS(D$2:$D26,외피index!$B$4,C$2:$C26,C26), IF($D26=외피index!$B$5, 외피index!$C$5&"_"&COUNTIFS(D$2:$D26,외피index!$B$5,C$2:$C26,C26), IF($D26=외피index!$B$6, 외피index!$C$6&"_"&COUNTIFS(D$2:$D26,외피index!$B$6,C$2:$C26,C26), IF($D26=외피index!$B$7, 외피index!$C$7&"_"&COUNTIFS(D$2:$D26,외피index!$B$7,C$2:$C26,C26), IF($D26=외피index!$B$8, 외피index!$C$8&"_"&COUNTIFS(D$2:$D26,외피index!$B$8,C$2:$C26,C26), IF($D26=외피index!$B$9, 외피index!$C$9&"_"&COUNTIFS(D$2:$D26,외피index!$B$9,C$2:$C26,C26), IF($D26=외피index!$B$10, 외피index!$C$10&"_"&COUNTIFS(D$2:$D26,외피index!$B$10,C$2:$C26,C26), 0))))))))),"") -> 3F_Zone018_SL_1 | B26: 3F | C26: 3F_Zone018 | D26: 층간바닥 | F26: 1.3499908 | G26: 4F_Zone021 | H26: 수평 | I26: 180
A27: =IFERROR(IF(D27="","",C27&"_"& IF($D27=외피index!$B$3, 외피index!$C$3&"_"&COUNTIFS(D$2:$D27,외피index!$B$3,C$2:$C27,C27), IF($D27=외피index!$B$4, 외피index!$C$4&"_"&COUNTIFS(D$2:$D27,외피index!$B$4,C$2:$C27,C27), IF($D27=외피index!$B$5, 외피index!$C$5&"_"&COUNTIFS(D$2:$D27,외피index!$B$5,C$2:$C27,C27), IF($D27=외피index!$B$6, 외피index!$C$6&"_"&COUNTIFS(D$2:$D27,외피index!$B$6,C$2:$C27,C27), IF($D27=외피index!$B$7, 외피index!$C$7&"_"&COUNTIFS(D$2:$D27,외피index!$B$7,C$2:$C27,C27), IF($D27=외피index!$B$8, 외피index!$C$8&"_"&COUNTIFS(D$2:$D27,외피index!$B$8,C$2:$C27,C27), IF($D27=외피index!$B$9, 외피index!$C$9&"_"&COUNTIFS(D$2:$D27,외피index!$B$9,C$2:$C27,C27), IF($D27=외피index!$B$10, 외피index!$C$10&"_"&COUNTIFS(D$2:$D27,외피index!$B$10,C$2:$C27,C27), 0))))))))),"") -> 1F_Zone002_SL_1 | B27: 1F | C27: 1F_Zone002 | D27: 층간바닥 | F27: 42.639959 | G27: 2F_Zone006 | H27: 수평 | I27: 0
A28: =IFERROR(IF(D28="","",C28&"_"& IF($D28=외피index!$B$3, 외피index!$C$3&"_"&COUNTIFS(D$2:$D28,외피index!$B$3,C$2:$C28,C28), IF($D28=외피index!$B$4, 외피index!$C$4&"_"&COUNTIFS(D$2:$D28,외피index!$B$4,C$2:$C28,C28), IF($D28=외피index!$B$5, 외피index!$C$5&"_"&COUNTIFS(D$2:$D28,외피index!$B$5,C$2:$C28,C28), IF($D28=외피index!$B$6, 외피index!$C$6&"_"&COUNTIFS(D$2:$D28,외피index!$B$6,C$2:$C28,C28), IF($D28=외피index!$B$7, 외피index!$C$7&"_"&COUNTIFS(D$2:$D28,외피index!$B$7,C$2:$C28,C28), IF($D28=외피index!$B$8, 외피index!$C$8&"_"&COUNTIFS(D$2:$D28,외피index!$B$8,C$2:$C28,C28), IF($D28=외피index!$B$9, 외피index!$C$9&"_"&COUNTIFS(D$2:$D28,외피index!$B$9,C$2:$C28,C28), IF($D28=외피index!$B$10, 외피index!$C$10&"_"&COUNTIFS(D$2:$D28,외피index!$B$10,C$2:$C28,C28), 0))))))))),"") -> 1F_Zone003_SL_1 | B28: 1F | C28: 1F_Zone003 | D28: 층간바닥 | F28: 16.799957 | G28: 2F_Zone008 | H28: 수평 | I28: 180
A29: =IFERROR(IF(D29="","",C29&"_"& IF($D29=외피index!$B$3, 외피index!$C$3&"_"&COUNTIFS(D$2:$D29,외피index!$B$3,C$2:$C29,C29), IF($D29=외피index!$B$4, 외피index!$C$4&"_"&COUNTIFS(D$2:$D29,외피index!$B$4,C$2:$C29,C29), IF($D29=외피index!$B$5, 외피index!$C$5&"_"&COUNTIFS(D$2:$D29,외피index!$B$5,C$2:$C29,C29), IF($D29=외피index!$B$6, 외피index!$C$6&"_"&COUNTIFS(D$2:$D29,외피index!$B$6,C$2:$C29,C29), IF($D29=외피index!$B$7, 외피index!$C$7&"_"&COUNTIFS(D$2:$D29,외피index!$B$7,C$2:$C29,C29), IF($D29=외피index!$B$8, 외피index!$C$8&"_"&COUNTIFS(D$2:$D29,외피index!$B$8,C$2:$C29,C29), IF($D29=외피index!$B$9, 외피index!$C$9&"_"&COUNTIFS(D$2:$D29,외피index!$B$9,C$2:$C29,C29), IF($D29=외피index!$B$10, 외피index!$C$10&"_"&COUNTIFS(D$2:$D29,외피index!$B$10,C$2:$C29,C29), 0))))))))),"") -> 1F_Zone004_SL_1 | B29: 1F | C29: 1F_Zone004 | D29: 층간바닥 | F29: 10.920057 | G29: 2F_Zone011 | H29: 수평 | I29: 180
A30: =IFERROR(IF(D30="","",C30&"_"& IF($D30=외피index!$B$3, 외피index!$C$3&"_"&COUNTIFS(D$2:$D30,외피index!$B$3,C$2:$C30,C30), IF($D30=외피index!$B$4, 외피index!$C$4&"_"&COUNTIFS(D$2:$D30,외피index!$B$4,C$2:$C30,C30), IF($D30=외피index!$B$5, 외피index!$C$5&"_"&COUNTIFS(D$2:$D30,외피index!$B$5,C$2:$C30,C30), IF($D30=외피index!$B$6, 외피index!$C$6&"_"&COUNTIFS(D$2:$D30,외피index!$B$6,C$2:$C30,C30), IF($D30=외피index!$B$7, 외피index!$C$7&"_"&COUNTIFS(D$2:$D30,외피index!$B$7,C$2:$C30,C30), IF($D30=외피index!$B$8, 외피index!$C$8&"_"&COUNTIFS(D$2:$D30,외피index!$B$8,C$2:$C30,C30), IF($D30=외피index!$B$9, 외피index!$C$9&"_"&COUNTIFS(D$2:$D30,외피index!$B$9,C$2:$C30,C30), IF($D30=외피index!$B$10, 외피index!$C$10&"_"&COUNTIFS(D$2:$D30,외피index!$B$10,C$2:$C30,C30), 0))))))))),"") -> 1F_Zone003_SL_2 | B30: 1F | C30: 1F_Zone003 | D30: 층간바닥 | F30: 7.2799854 | G30: 2F_Zone011 | H30: 수평 | I30: 180
A31: =IFERROR(IF(D31="","",C31&"_"& IF($D31=외피index!$B$3, 외피index!$C$3&"_"&COUNTIFS(D$2:$D31,외피index!$B$3,C$2:$C31,C31), IF($D31=외피index!$B$4, 외피index!$C$4&"_"&COUNTIFS(D$2:$D31,외피index!$B$4,C$2:$C31,C31), IF($D31=외피index!$B$5, 외피index!$C$5&"_"&COUNTIFS(D$2:$D31,외피index!$B$5,C$2:$C31,C31), IF($D31=외피index!$B$6, 외피index!$C$6&"_"&COUNTIFS(D$2:$D31,외피index!$B$6,C$2:$C31,C31), IF($D31=외피index!$B$7, 외피index!$C$7&"_"&COUNTIFS(D$2:$D31,외피index!$B$7,C$2:$C31,C31), IF($D31=외피index!$B$8, 외피index!$C$8&"_"&COUNTIFS(D$2:$D31,외피index!$B$8,C$2:$C31,C31), IF($D31=외피index!$B$9, 외피index!$C$9&"_"&COUNTIFS(D$2:$D31,외피index!$B$9,C$2:$C31,C31), IF($D31=외피index!$B$10, 외피index!$C$10&"_"&COUNTIFS(D$2:$D31,외피index!$B$10,C$2:$C31,C31), 0))))))))),"") -> 4F_Zone021_RF_1 | B31: 4F | C31: 4F_Zone021 | D31: 지붕 | F31: 16.799957 | H31: 수평 | I31: 0
A32: =IFERROR(IF(D32="","",C32&"_"& IF($D32=외피index!$B$3, 외피index!$C$3&"_"&COUNTIFS(D$2:$D32,외피index!$B$3,C$2:$C32,C32), IF($D32=외피index!$B$4, 외피index!$C$4&"_"&COUNTIFS(D$2:$D32,외피index!$B$4,C$2:$C32,C32), IF($D32=외피index!$B$5, 외피index!$C$5&"_"&COUNTIFS(D$2:$D32,외피index!$B$5,C$2:$C32,C32), IF($D32=외피index!$B$6, 외피index!$C$6&"_"&COUNTIFS(D$2:$D32,외피index!$B$6,C$2:$C32,C32), IF($D32=외피index!$B$7, 외피index!$C$7&"_"&COUNTIFS(D$2:$D32,외피index!$B$7,C$2:$C32,C32), IF($D32=외피index!$B$8, 외피index!$C$8&"_"&COUNTIFS(D$2:$D32,외피index!$B$8,C$2:$C32,C32), IF($D32=외피index!$B$9, 외피index!$C$9&"_"&COUNTIFS(D$2:$D32,외피index!$B$9,C$2:$C32,C32), IF($D32=외피index!$B$10, 외피index!$C$10&"_"&COUNTIFS(D$2:$D32,외피index!$B$10,C$2:$C32,C32), 0))))))))),"") -> 1F_Zone005_RF_1 | B32: 1F | C32: 1F_Zone005 | D32: 지붕 | F32: 3.7170383 | H32: 수평 | I32: 0
A33: =IFERROR(IF(D33="","",C33&"_"& IF($D33=외피index!$B$3, 외피index!$C$3&"_"&COUNTIFS(D$2:$D33,외피index!$B$3,C$2:$C33,C33), IF($D33=외피index!$B$4, 외피index!$C$4&"_"&COUNTIFS(D$2:$D33,외피index!$B$4,C$2:$C33,C33), IF($D33=외피index!$B$5, 외피index!$C$5&"_"&COUNTIFS(D$2:$D33,외피index!$B$5,C$2:$C33,C33), IF($D33=외피index!$B$6, 외피index!$C$6&"_"&COUNTIFS(D$2:$D33,외피index!$B$6,C$2:$C33,C33), IF($D33=외피index!$B$7, 외피index!$C$7&"_"&COUNTIFS(D$2:$D33,외피index!$B$7,C$2:$C33,C33), IF($D33=외피index!$B$8, 외피index!$C$8&"_"&COUNTIFS(D$2:$D33,외피index!$B$8,C$2:$C33,C33), IF($D33=외피index!$B$9, 외피index!$C$9&"_"&COUNTIFS(D$2:$D33,외피index!$B$9,C$2:$C33,C33), IF($D33=외피index!$B$10, 외피index!$C$10&"_"&COUNTIFS(D$2:$D33,외피index!$B$10,C$2:$C33,C33), 0))))))))),"") -> 3F_Zone014_SL_1 | B33: 3F | C33: 3F_Zone014 | D33: 층간바닥 | F33: 28.080031 | G33: 2F_Zone006 | H33: 수평 | I33: 180
A34: =IFERROR(IF(D34="","",C34&"_"& IF($D34=외피index!$B$3, 외피index!$C$3&"_"&COUNTIFS(D$2:$D34,외피index!$B$3,C$2:$C34,C34), IF($D34=외피index!$B$4, 외피index!$C$4&"_"&COUNTIFS(D$2:$D34,외피index!$B$4,C$2:$C34,C34), IF($D34=외피index!$B$5, 외피index!$C$5&"_"&COUNTIFS(D$2:$D34,외피index!$B$5,C$2:$C34,C34), IF($D34=외피index!$B$6, 외피index!$C$6&"_"&COUNTIFS(D$2:$D34,외피index!$B$6,C$2:$C34,C34), IF($D34=외피index!$B$7, 외피index!$C$7&"_"&COUNTIFS(D$2:$D34,외피index!$B$7,C$2:$C34,C34), IF($D34=외피index!$B$8, 외피index!$C$8&"_"&COUNTIFS(D$2:$D34,외피index!$B$8,C$2:$C34,C34), IF($D34=외피index!$B$9, 외피index!$C$9&"_"&COUNTIFS(D$2:$D34,외피index!$B$9,C$2:$C34,C34), IF($D34=외피index!$B$10, 외피index!$C$10&"_"&COUNTIFS(D$2:$D34,외피index!$B$10,C$2:$C34,C34), 0))))))))),"") -> 3F_Zone015_SL_1 | B34: 3F | C34: 3F_Zone015 | D34: 층간바닥 | F34: 22.879955 | G34: 2F_Zone007 | H34: 수평 | I34: 180
A35: =IFERROR(IF(D35="","",C35&"_"& IF($D35=외피index!$B$3, 외피index!$C$3&"_"&COUNTIFS(D$2:$D35,외피index!$B$3,C$2:$C35,C35), IF($D35=외피index!$B$4, 외피index!$C$4&"_"&COUNTIFS(D$2:$D35,외피index!$B$4,C$2:$C35,C35), IF($D35=외피index!$B$5, 외피index!$C$5&"_"&COUNTIFS(D$2:$D35,외피index!$B$5,C$2:$C35,C35), IF($D35=외피index!$B$6, 외피index!$C$6&"_"&COUNTIFS(D$2:$D35,외피index!$B$6,C$2:$C35,C35), IF($D35=외피index!$B$7, 외피index!$C$7&"_"&COUNTIFS(D$2:$D35,외피index!$B$7,C$2:$C35,C35), IF($D35=외피index!$B$8, 외피index!$C$8&"_"&COUNTIFS(D$2:$D35,외피index!$B$8,C$2:$C35,C35), IF($D35=외피index!$B$9, 외피index!$C$9&"_"&COUNTIFS(D$2:$D35,외피index!$B$9,C$2:$C35,C35), IF($D35=외피index!$B$10, 외피index!$C$10&"_"&COUNTIFS(D$2:$D35,외피index!$B$10,C$2:$C35,C35), 0))))))))),"") -> 3F_Zone016_SL_2 | B35: 3F | C35: 3F_Zone016 | D35: 층간바닥 | F35: 15.449966 | G35: 2F_Zone008 | H35: 수평 | I35: 0
A36: =IFERROR(IF(D36="","",C36&"_"& IF($D36=외피index!$B$3, 외피index!$C$3&"_"&COUNTIFS(D$2:$D36,외피index!$B$3,C$2:$C36,C36), IF($D36=외피index!$B$4, 외피index!$C$4&"_"&COUNTIFS(D$2:$D36,외피index!$B$4,C$2:$C36,C36), IF($D36=외피index!$B$5, 외피index!$C$5&"_"&COUNTIFS(D$2:$D36,외피index!$B$5,C$2:$C36,C36), IF($D36=외피index!$B$6, 외피index!$C$6&"_"&COUNTIFS(D$2:$D36,외피index!$B$6,C$2:$C36,C36), IF($D36=외피index!$B$7, 외피index!$C$7&"_"&COUNTIFS(D$2:$D36,외피index!$B$7,C$2:$C36,C36), IF($D36=외피index!$B$8, 외피index!$C$8&"_"&COUNTIFS(D$2:$D36,외피index!$B$8,C$2:$C36,C36), IF($D36=외피index!$B$9, 외피index!$C$9&"_"&COUNTIFS(D$2:$D36,외피index!$B$9,C$2:$C36,C36), IF($D36=외피index!$B$10, 외피index!$C$10&"_"&COUNTIFS(D$2:$D36,외피index!$B$10,C$2:$C36,C36), 0))))))))),"") -> 3F_Zone015_SL_2 | B36: 3F | C36: 3F_Zone015 | D36: 층간바닥 | F36: 14.040055 | G36: 2F_Zone009 | H36: 수평 | I36: 180
A37: =IFERROR(IF(D37="","",C37&"_"& IF($D37=외피index!$B$3, 외피index!$C$3&"_"&COUNTIFS(D$2:$D37,외피index!$B$3,C$2:$C37,C37), IF($D37=외피index!$B$4, 외피index!$C$4&"_"&COUNTIFS(D$2:$D37,외피index!$B$4,C$2:$C37,C37), IF($D37=외피index!$B$5, 외피index!$C$5&"_"&COUNTIFS(D$2:$D37,외피index!$B$5,C$2:$C37,C37), IF($D37=외피index!$B$6, 외피index!$C$6&"_"&COUNTIFS(D$2:$D37,외피index!$B$6,C$2:$C37,C37), IF($D37=외피index!$B$7, 외피index!$C$7&"_"&COUNTIFS(D$2:$D37,외피index!$B$7,C$2:$C37,C37), IF($D37=외피index!$B$8, 외피index!$C$8&"_"&COUNTIFS(D$2:$D37,외피index!$B$8,C$2:$C37,C37), IF($D37=외피index!$B$9, 외피index!$C$9&"_"&COUNTIFS(D$2:$D37,외피index!$B$9,C$2:$C37,C37), IF($D37=외피index!$B$10, 외피index!$C$10&"_"&COUNTIFS(D$2:$D37,외피index!$B$10,C$2:$C37,C37), 0))))))))),"") -> 3F_Zone017_SL_1 | B37: 3F | C37: 3F_Zone017 | D37: 층간바닥 | F37: 8.6799365 | G37: 2F_Zone006 | H37: 수평 | I37: 180
A38: =IFERROR(IF(D38="","",C38&"_"& IF($D38=외피index!$B$3, 외피index!$C$3&"_"&COUNTIFS(D$2:$D38,외피index!$B$3,C$2:$C38,C38), IF($D38=외피index!$B$4, 외피index!$C$4&"_"&COUNTIFS(D$2:$D38,외피index!$B$4,C$2:$C38,C38), IF($D38=외피index!$B$5, 외피index!$C$5&"_"&COUNTIFS(D$2:$D38,외피index!$B$5,C$2:$C38,C38), IF($D38=외피index!$B$6, 외피index!$C$6&"_"&COUNTIFS(D$2:$D38,외피index!$B$6,C$2:$C38,C38), IF($D38=외피index!$B$7, 외피index!$C$7&"_"&COUNTIFS(D$2:$D38,외피index!$B$7,C$2:$C38,C38), IF($D38=외피index!$B$8, 외피index!$C$8&"_"&COUNTIFS(D$2:$D38,외피index!$B$8,C$2:$C38,C38), IF($D38=외피index!$B$9, 외피index!$C$9&"_"&COUNTIFS(D$2:$D38,외피index!$B$9,C$2:$C38,C38), IF($D38=외피index!$B$10, 외피index!$C$10&"_"&COUNTIFS(D$2:$D38,외피index!$B$10,C$2:$C38,C38), 0))))))))),"") -> 3F_Zone016_SL_3 | B38: 3F | C38: 3F_Zone016 | D38: 층간바닥 | F38: 5.8799915 | G38: 2F_Zone006 | H38: 수평 | I38: 0
A39: =IFERROR(IF(D39="","",C39&"_"& IF($D39=외피index!$B$3, 외피index!$C$3&"_"&COUNTIFS(D$2:$D39,외피index!$B$3,C$2:$C39,C39), IF($D39=외피index!$B$4, 외피index!$C$4&"_"&COUNTIFS(D$2:$D39,외피index!$B$4,C$2:$C39,C39), IF($D39=외피index!$B$5, 외피index!$C$5&"_"&COUNTIFS(D$2:$D39,외피index!$B$5,C$2:$C39,C39), IF($D39=외피index!$B$6, 외피index!$C$6&"_"&COUNTIFS(D$2:$D39,외피index!$B$6,C$2:$C39,C39), IF($D39=외피index!$B$7, 외피index!$C$7&"_"&COUNTIFS(D$2:$D39,외피index!$B$7,C$2:$C39,C39), IF($D39=외피index!$B$8, 외피index!$C$8&"_"&COUNTIFS(D$2:$D39,외피index!$B$8,C$2:$C39,C39), IF($D39=외피index!$B$9, 외피index!$C$9&"_"&COUNTIFS(D$2:$D39,외피index!$B$9,C$2:$C39,C39), IF($D39=외피index!$B$10, 외피index!$C$10&"_"&COUNTIFS(D$2:$D39,외피index!$B$10,C$2:$C39,C39), 0))))))))),"") -> 3F_Zone019_SL_1 | B39: 3F | C39: 3F_Zone019 | D39: 층간바닥 | F39: 5.5822345 | G39: 2F_Zone008 | H39: 수평 | I39: 0
A40: =IFERROR(IF(D40="","",C40&"_"& IF($D40=외피index!$B$3, 외피index!$C$3&"_"&COUNTIFS(D$2:$D40,외피index!$B$3,C$2:$C40,C40), IF($D40=외피index!$B$4, 외피index!$C$4&"_"&COUNTIFS(D$2:$D40,외피index!$B$4,C$2:$C40,C40), IF($D40=외피index!$B$5, 외피index!$C$5&"_"&COUNTIFS(D$2:$D40,외피index!$B$5,C$2:$C40,C40), IF($D40=외피index!$B$6, 외피index!$C$6&"_"&COUNTIFS(D$2:$D40,외피index!$B$6,C$2:$C40,C40), IF($D40=외피index!$B$7, 외피index!$C$7&"_"&COUNTIFS(D$2:$D40,외피index!$B$7,C$2:$C40,C40), IF($D40=외피index!$B$8, 외피index!$C$8&"_"&COUNTIFS(D$2:$D40,외피index!$B$8,C$2:$C40,C40), IF($D40=외피index!$B$9, 외피index!$C$9&"_"&COUNTIFS(D$2:$D40,외피index!$B$9,C$2:$C40,C40), IF($D40=외피index!$B$10, 외피index!$C$10&"_"&COUNTIFS(D$2:$D40,외피index!$B$10,C$2:$C40,C40), 0))))))))),"") -> 3F_Zone020_SL_1 | B40: 3F | C40: 3F_Zone020 | D40: 층간바닥 | F40: 4.7999878 | G40: 2F_Zone013 | H40: 수평 | I40: 180
...

Sheet ThermalBridge_3D
A1: 번호 | B1: 열교항목 | C1: 열교길이
A2: =IF(B2="","",INDEX(외피index!$C$69:$C$79,MATCH(B2,외피index!$B$69:$B$79,0),1)&"_"& IF(B2=외피index!$B$69,COUNTIF($B$2:B2,외피index!$B$69), IF(B2=외피index!$B$70,COUNTIF($B$2:B2,외피index!$B$70), IF(B2=외피index!$B$71,COUNTIF($B$2:B2,외피index!$B$71), IF(B2=외피index!$B$72,COUNTIF($B$2:B2,외피index!$B$72), IF(B2=외피index!$B$73,COUNTIF($B$2:B2,외피index!$B$73), IF(B2=외피index!$B$74,COUNTIF($B$2:B2,외피index!$B$74), IF(B2=외피index!$B$75,COUNTIF($B$2:B2,외피index!$B$75), IF(B2=외피index!$B$76,COUNTIF($B$2:B2,외피index!$B$76), IF(B2=외피index!$B$77,COUNTIF($B$2:B2,외피index!$B$77), IF(B2=외피index!$B$78,COUNTIF($B$2:B2,외피index!$B$78), IF(B2=외피index!$B$79,COUNTIF($B$2:B2,외피index!$B$79))))))))))))) -> TB1_1 | B2: 평지붕+외벽[90] | C2: 118.09
A3: =IF(B3="","",INDEX(외피index!$C$69:$C$79,MATCH(B3,외피index!$B$69:$B$79,0),1)&"_"& IF(B3=외피index!$B$69,COUNTIF($B$2:B3,외피index!$B$69), IF(B3=외피index!$B$70,COUNTIF($B$2:B3,외피index!$B$70), IF(B3=외피index!$B$71,COUNTIF($B$2:B3,외피index!$B$71), IF(B3=외피index!$B$72,COUNTIF($B$2:B3,외피index!$B$72), IF(B3=외피index!$B$73,COUNTIF($B$2:B3,외피index!$B$73), IF(B3=외피index!$B$74,COUNTIF($B$2:B3,외피index!$B$74), IF(B3=외피index!$B$75,COUNTIF($B$2:B3,외피index!$B$75), IF(B3=외피index!$B$76,COUNTIF($B$2:B3,외피index!$B$76), IF(B3=외피index!$B$77,COUNTIF($B$2:B3,외피index!$B$77), IF(B3=외피index!$B$78,COUNTIF($B$2:B3,외피index!$B$78), IF(B3=외피index!$B$79,COUNTIF($B$2:B3,외피index!$B$79))))))))))))) -> TB1_2 | B3: 평지붕+외벽[90] | C3: 100
A4: =IF(B4="","",INDEX(외피index!$C$69:$C$79,MATCH(B4,외피index!$B$69:$B$79,0),1)&"_"& IF(B4=외피index!$B$69,COUNTIF($B$2:B4,외피index!$B$69), IF(B4=외피index!$B$70,COUNTIF($B$2:B4,외피index!$B$70), IF(B4=외피index!$B$71,COUNTIF($B$2:B4,외피index!$B$71), IF(B4=외피index!$B$72,COUNTIF($B$2:B4,외피index!$B$72), IF(B4=외피index!$B$73,COUNTIF($B$2:B4,외피index!$B$73), IF(B4=외피index!$B$74,COUNTIF($B$2:B4,외피index!$B$74), IF(B4=외피index!$B$75,COUNTIF($B$2:B4,외피index!$B$75), IF(B4=외피index!$B$76,COUNTIF($B$2:B4,외피index!$B$76), IF(B4=외피index!$B$77,COUNTIF($B$2:B4,외피index!$B$77), IF(B4=외피index!$B$78,COUNTIF($B$2:B4,외피index!$B$78), IF(B4=외피index!$B$79,COUNTIF($B$2:B4,외피index!$B$79))))))))))))) -> TB1_3 | B4: 평지붕+외벽[90] | C4: 50
A5: =IF(B5="","",INDEX(외피index!$C$69:$C$79,MATCH(B5,외피index!$B$69:$B$79,0),1)&"_"& IF(B5=외피index!$B$69,COUNTIF($B$2:B5,외피index!$B$69), IF(B5=외피index!$B$70,COUNTIF($B$2:B5,외피index!$B$70), IF(B5=외피index!$B$71,COUNTIF($B$2:B5,외피index!$B$71), IF(B5=외피index!$B$72,COUNTIF($B$2:B5,외피index!$B$72), IF(B5=외피index!$B$73,COUNTIF($B$2:B5,외피index!$B$73), IF(B5=외피index!$B$74,COUNTIF($B$2:B5,외피index!$B$74), IF(B5=외피index!$B$75,COUNTIF($B$2:B5,외피index!$B$75), IF(B5=외피index!$B$76,COUNTIF($B$2:B5,외피index!$B$76), IF(B5=외피index!$B$77,COUNTIF($B$2:B5,외피index!$B$77), IF(B5=외피index!$B$78,COUNTIF($B$2:B5,외피index!$B$78), IF(B5=외피index!$B$79,COUNTIF($B$2:B5,외피index!$B$79))))))))))))) -> TB2_1 | B5: 평지붕+내벽 | C5: 41.25
A6: =IF(B6="","",INDEX(외피index!$C$69:$C$79,MATCH(B6,외피index!$B$69:$B$79,0),1)&"_"& IF(B6=외피index!$B$69,COUNTIF($B$2:B6,외피index!$B$69), IF(B6=외피index!$B$70,COUNTIF($B$2:B6,외피index!$B$70), IF(B6=외피index!$B$71,COUNTIF($B$2:B6,외피index!$B$71), IF(B6=외피index!$B$72,COUNTIF($B$2:B6,외피index!$B$72), IF(B6=외피index!$B$73,COUNTIF($B$2:B6,외피index!$B$73), IF(B6=외피index!$B$74,COUNTIF($B$2:B6,외피index!$B$74), IF(B6=외피index!$B$75,COUNTIF($B$2:B6,외피index!$B$75), IF(B6=외피index!$B$76,COUNTIF($B$2:B6,외피index!$B$76), IF(B6=외피index!$B$77,COUNTIF($B$2:B6,외피index!$B$77), IF(B6=외피index!$B$78,COUNTIF($B$2:B6,외피index!$B$78), IF(B6=외피index!$B$79,COUNTIF($B$2:B6,외피index!$B$79))))))))))))) -> TB3_1 | B6: 경사지붕 | C6: 0
A7: =IF(B7="","",INDEX(외피index!$C$69:$C$79,MATCH(B7,외피index!$B$69:$B$79,0),1)&"_"& IF(B7=외피index!$B$69,COUNTIF($B$2:B7,외피index!$B$69), IF(B7=외피index!$B$70,COUNTIF($B$2:B7,외피index!$B$70), IF(B7=외피index!$B$71,COUNTIF($B$2:B7,외피index!$B$71), IF(B7=외피index!$B$72,COUNTIF($B$2:B7,외피index!$B$72), IF(B7=외피index!$B$73,COUNTIF($B$2:B7,외피index!$B$73), IF(B7=외피index!$B$74,COUNTIF($B$2:B7,외피index!$B$74), IF(B7=외피index!$B$75,COUNTIF($B$2:B7,외피index!$B$75), IF(B7=외피index!$B$76,COUNTIF($B$2:B7,외피index!$B$76), IF(B7=외피index!$B$77,COUNTIF($B$2:B7,외피index!$B$77), IF(B7=외피index!$B$78,COUNTIF($B$2:B7,외피index!$B$78), IF(B7=외피index!$B$79,COUNTIF($B$2:B7,외피index!$B$79))))))))))))) -> TB4_1 | B7: 경사지붕+벽 | C7: 0
A8: =IF(B8="","",INDEX(외피index!$C$69:$C$79,MATCH(B8,외피index!$B$69:$B$79,0),1)&"_"& IF(B8=외피index!$B$69,COUNTIF($B$2:B8,외피index!$B$69), IF(B8=외피index!$B$70,COUNTIF($B$2:B8,외피index!$B$70), IF(B8=외피index!$B$71,COUNTIF($B$2:B8,외피index!$B$71), IF(B8=외피index!$B$72,COUNTIF($B$2:B8,외피index!$B$72), IF(B8=외피index!$B$73,COUNTIF($B$2:B8,외피index!$B$73), IF(B8=외피index!$B$74,COUNTIF($B$2:B8,외피index!$B$74), IF(B8=외피index!$B$75,COUNTIF($B$2:B8,외피index!$B$75), IF(B8=외피index!$B$76,COUNTIF($B$2:B8,외피index!$B$76), IF(B8=외피index!$B$77,COUNTIF($B$2:B8,외피index!$B$77), IF(B8=외피index!$B$78,COUNTIF($B$2:B8,외피index!$B$78), IF(B8=외피index!$B$79,COUNTIF($B$2:B8,외피index!$B$79))))))))))))) -> TB5_1 | B8: 경사지붕+경사벽 | C8: 0
A9: =IF(B9="","",INDEX(외피index!$C$69:$C$79,MATCH(B9,외피index!$B$69:$B$79,0),1)&"_"& IF(B9=외피index!$B$69,COUNTIF($B$2:B9,외피index!$B$69), IF(B9=외피index!$B$70,COUNTIF($B$2:B9,외피index!$B$70), IF(B9=외피index!$B$71,COUNTIF($B$2:B9,외피index!$B$71), IF(B9=외피index!$B$72,COUNTIF($B$2:B9,외피index!$B$72), IF(B9=외피index!$B$73,COUNTIF($B$2:B9,외피index!$B$73), IF(B9=외피index!$B$74,COUNTIF($B$2:B9,외피index!$B$74), IF(B9=외피index!$B$75,COUNTIF($B$2:B9,외피index!$B$75), IF(B9=외피index!$B$76,COUNTIF($B$2:B9,외피index!$B$76), IF(B9=외피index!$B$77,COUNTIF($B$2:B9,외피index!$B$77), IF(B9=외피index!$B$78,COUNTIF($B$2:B9,외피index!$B$78), IF(B9=외피index!$B$79,COUNTIF($B$2:B9,외피index!$B$79))))))))))))) -> TB6_1 | B9: 슬라브+벽 | C9: 67.7
A10: =IF(B10="","",INDEX(외피index!$C$69:$C$79,MATCH(B10,외피index!$B$69:$B$79,0),1)&"_"& IF(B10=외피index!$B$69,COUNTIF($B$2:B10,외피index!$B$69), IF(B10=외피index!$B$70,COUNTIF($B$2:B10,외피index!$B$70), IF(B10=외피index!$B$71,COUNTIF($B$2:B10,외피index!$B$71), IF(B10=외피index!$B$72,COUNTIF($B$2:B10,외피index!$B$72), IF(B10=외피index!$B$73,COUNTIF($B$2:B10,외피index!$B$73), IF(B10=외피index!$B$74,COUNTIF($B$2:B10,외피index!$B$74), IF(B10=외피index!$B$75,COUNTIF($B$2:B10,외피index!$B$75), IF(B10=외피index!$B$76,COUNTIF($B$2:B10,외피index!$B$76), IF(B10=외피index!$B$77,COUNTIF($B$2:B10,외피index!$B$77), IF(B10=외피index!$B$78,COUNTIF($B$2:B10,외피index!$B$78), IF(B10=외피index!$B$79,COUNTIF($B$2:B10,외피index!$B$79))))))))))))) -> TB7_1 | B10: 내벽+외벽 | C10: 54.8
A11: =IF(B11="","",INDEX(외피index!$C$69:$C$79,MATCH(B11,외피index!$B$69:$B$79,0),1)&"_"& IF(B11=외피index!$B$69,COUNTIF($B$2:B11,외피index!$B$69), IF(B11=외피index!$B$70,COUNTIF($B$2:B11,외피index!$B$70), IF(B11=외피index!$B$71,COUNTIF($B$2:B11,외피index!$B$71), IF(B11=외피index!$B$72,COUNTIF($B$2:B11,외피index!$B$72), IF(B11=외피index!$B$73,COUNTIF($B$2:B11,외피index!$B$73), IF(B11=외피index!$B$74,COUNTIF($B$2:B11,외피index!$B$74), IF(B11=외피index!$B$75,COUNTIF($B$2:B11,외피index!$B$75), IF(B11=외피index!$B$76,COUNTIF($B$2:B11,외피index!$B$76), IF(B11=외피index!$B$77,COUNTIF($B$2:B11,외피index!$B$77), IF(B11=외피index!$B$78,COUNTIF($B$2:B11,외피index!$B$78), IF(B11=외피index!$B$79,COUNTIF($B$2:B11,외피index!$B$79))))))))))))) -> TB8_1 | B11: 외벽+외벽 | C11: 144.33
A12: =IF(B12="","",INDEX(외피index!$C$69:$C$79,MATCH(B12,외피index!$B$69:$B$79,0),1)&"_"& IF(B12=외피index!$B$69,COUNTIF($B$2:B12,외피index!$B$69), IF(B12=외피index!$B$70,COUNTIF($B$2:B12,외피index!$B$70), IF(B12=외피index!$B$71,COUNTIF($B$2:B12,외피index!$B$71), IF(B12=외피index!$B$72,COUNTIF($B$2:B12,외피index!$B$72), IF(B12=외피index!$B$73,COUNTIF($B$2:B12,외피index!$B$73), IF(B12=외피index!$B$74,COUNTIF($B$2:B12,외피index!$B$74), IF(B12=외피index!$B$75,COUNTIF($B$2:B12,외피index!$B$75), IF(B12=외피index!$B$76,COUNTIF($B$2:B12,외피index!$B$76), IF(B12=외피index!$B$77,COUNTIF($B$2:B12,외피index!$B$77), IF(B12=외피index!$B$78,COUNTIF($B$2:B12,외피index!$B$78), IF(B12=외피index!$B$79,COUNTIF($B$2:B12,외피index!$B$79))))))))))))) -> TB9_1 | B12: 외벽+내벽+외벽 | C12: 18.2
A13: =IF(B13="","",INDEX(외피index!$C$69:$C$79,MATCH(B13,외피index!$B$69:$B$79,0),1)&"_"& IF(B13=외피index!$B$69,COUNTIF($B$2:B13,외피index!$B$69), IF(B13=외피index!$B$70,COUNTIF($B$2:B13,외피index!$B$70), IF(B13=외피index!$B$71,COUNTIF($B$2:B13,외피index!$B$71), IF(B13=외피index!$B$72,COUNTIF($B$2:B13,외피index!$B$72), IF(B13=외피index!$B$73,COUNTIF($B$2:B13,외피index!$B$73), IF(B13=외피index!$B$74,COUNTIF($B$2:B13,외피index!$B$74), IF(B13=외피index!$B$75,COUNTIF($B$2:B13,외피index!$B$75), IF(B13=외피index!$B$76,COUNTIF($B$2:B13,외피index!$B$76), IF(B13=외피index!$B$77,COUNTIF($B$2:B13,외피index!$B$77), IF(B13=외피index!$B$78,COUNTIF($B$2:B13,외피index!$B$78), IF(B13=외피index!$B$79,COUNTIF($B$2:B13,외피index!$B$79))))))))))))) -> TB10_1 | B13: 평지붕+벽[270] | C13: 9.25
A14: =IF(B14="","",INDEX(외피index!$C$69:$C$79,MATCH(B14,외피index!$B$69:$B$79,0),1)&"_"& IF(B14=외피index!$B$69,COUNTIF($B$2:B14,외피index!$B$69), IF(B14=외피index!$B$70,COUNTIF($B$2:B14,외피index!$B$70), IF(B14=외피index!$B$71,COUNTIF($B$2:B14,외피index!$B$71), IF(B14=외피index!$B$72,COUNTIF($B$2:B14,외피index!$B$72), IF(B14=외피index!$B$73,COUNTIF($B$2:B14,외피index!$B$73), IF(B14=외피index!$B$74,COUNTIF($B$2:B14,외피index!$B$74), IF(B14=외피index!$B$75,COUNTIF($B$2:B14,외피index!$B$75), IF(B14=외피index!$B$76,COUNTIF($B$2:B14,외피index!$B$76), IF(B14=외피index!$B$77,COUNTIF($B$2:B14,외피index!$B$77), IF(B14=외피index!$B$78,COUNTIF($B$2:B14,외피index!$B$78), IF(B14=외피index!$B$79,COUNTIF($B$2:B14,외피index!$B$79))))))))))))) -> TB11_1 | B14: 평지붕+벽[270]+내벽 | C14: 14.25

Sheet 외피index
A2: 외피 구조체 유형
A3: 1 | B3: 커튼월창 | C3: CW
A4: 2 | B4: 외벽 | C4: WL
A5: 3 | B5: 지붕 | C5: RF
A6: 4 | B6: 최하층바닥 | C6: FR
A7: 5 | B7: 창호 | C7: WIN
A8: 6 | B8: 외부출입문 | C8: DR
A9: 7 | B9: 내벽 | C9: IW
A10: 8 | B10: 층간바닥 | C10: SL
A12: 방위
A13: 0 | B13: 수평
A14: 1 | B14: 남
A15: 2 | B15: 남동
A16: 3 | B16: 남서
A17: 4 | B17: 동
A18: 5 | B18: 서
A19: 6 | B19: 북서
A20: 7 | B20: 북동
A21: 8 | B21: 북
A22: 9 | B22: -
A24: 커튼월 부위
A25: 1 | B25: 유리부분
A26: 2 | B26: 패널부분
A27: 3 | B27: 출입문부분
A28: 4 | B28: -
A31: 층
A32: B5 | B32: =A32&"F" -> B5F
A33: B4 | B33: =A33&"F" -> B4F
A34: B3 | B34: =A34&"F" -> B3F
A35: B2 | B35: =A35&"F" -> B2F
A36: B1 | B36: =A36&"F" -> B1F
A37: 1 | B37: =A37&"F" -> 1F
A38: 2 | B38: =A38&"F" -> 2F
A39: 3 | B39: =A39&"F" -> 3F
A40: 4 | B40: =A40&"F" -> 4F
A41: 5 | B41: =A41&"F" -> 5F
A42: 6 | B42: =A42&"F" -> 6F
A43: 7 | B43: =A43&"F" -> 7F
A44: 8 | B44: =A44&"F" -> 8F
A45: 9 | B45: =A45&"F" -> 9F
...
